Workbook

Sheet donnée
E1: IOL 700 | O1: IOL | AB1: POST OP J30 + ET KERATO AR | AK1: BARRETT | AN1: Haigis | AQ1: SRK/T | AT1: Zeiss | AW1: Cooke K6 | AZ1: EVO | BC1: Hill-RBF | BF1: Hoffer QST | BI1: Kane | BL1: Pearl DGS
A2: ID Patient | B2: Œil | C2: Âge | D2: antécédent | E2: AL | F2: ACD epit | G2: LT | H2: PACHY (mm) | I2: WTW (mm) | J2: K1 | K2: Axe | L2: K2 | M2: KM | N2: Astigmatisme cornéen | O2: K1 | P2: axe | Q2: K2 | R2: BARRETT SE attendu | S2: Haigis SE attendu | T2: SRK/T SE attendue | U2: ZEISS CALC | V2: Cooke K6 | W2: EVO | X2: Hill-RBF | Y2: Hoffer QST | Z2: Kane | AA2: Pearl DGS | AB2: Réfraction sphère | AC2: Réfraction cylindre | AD2: Réfraction axe | AE2: SE post-op | AF2: K1 | AG2: Axe | AH2: K2 | AI2: Astigmatisme cornéen | AJ2: SE attendu (Barrett) | AK2: Erreur SE (post-op - attendu) | AL2: Écart >0.50D ? | AM2: SE attendu Haigis | AN2: Erreur SE (post-op - attendu) | AO2: Écart >0.50D ? | AP2: SE attendu SRK/T | AQ2: Erreur SE (post-op - attendu) | AR2: Écart >0.50D ? | AS2: SE attendu Zeiss | AT2: Erreur SE (post-op - attendu) | AU2: Écart >0.50D ? | AV2: SE attendu Cooke k6 | AW2: Erreur SE (post-op - attendu) | AX2: Écart >0.50D ? | AY2: SE attendu EVO | AZ2: Erreur SE (post-op - attendu) | BA2: Écart >0.50D ? | BB2: SE attendu Hill-RBF | BC2: Erreur SE (post-op - attendu) | BD2: Écart >0.50D ? | BE2: SE attendu Hoffer QST | BF2: Erreur SE (post-op - attendu) | BG2: Écart >0.50D ? | BH2: SE attendu Kane | BI2: Erreur SE (post-op - attendu) | BJ2: Écart >0.50D ? | BK2: SE attendu Pearl DGS | BL2: Erreur SE (post-op - attendu) | BM2: Écart >0.50D ? | BN2: FORMULE LA PLUS PROCHE | BO2: PUISSANCE IOL =>30 | BP2: PUISSANCE IOL 30 => 25 | BQ2: PUISSANCE IOL 25 => 15 | BR2: PUISSANCE IOL 15 => 10 | BS2: PUISSANCE IOL 10 => 0 | BT2: PUISSANCE IOL 0=> | BU2: œil extrème >28mm | BV2: Œil très long 28>26 | BW2: Œil long 26>24,5 | BX2: Œil long NORMAL 24,5>22,5 | BY2: Œil court 22,5>20 | BZ2: Œil très court <20 | CA2: K extrème >48,5 | CB2: K CAMBRE 48,5>46,5 | CC2: K CAMBRE- 46,5>45 | CD2: K NORM 45>43 | CE2: K PLAT- 43>41 | CF2: K PLAT >41,0 | CG2: CA extrème >4,0 | CH2: CA profonde 4>3,5 | CI2: CA NORM 3,5>2,5 | CJ2: CA ETROITE 2,5>2,0 | CK2: CA tres etroite <2,0 | CL2: LT TRES EPAIS >5,3 | CM2: LT EPAIS 5,3>4,9 | CN2: LT NORMAL 4,9>3,8 | CO2: LT FIN>3,8 | CP2: WTW EXTREME >13 | CQ2: WTW GRAND 13>12,5 | CR2: WTW NORM 12,5>11,5 | CS2: WTW PETITE <11,5 | CT2: AGE +90 | CU2: AGE 89 => 80 | CV2: AGE 80 => 70 | CW2: AGE 69 => 60 | CX2: AGE 59 => 50 | CY2: AGE 49 => 40 | CZ2: AGE -39 | DA2: ANTECEDENT
DA75: =D75 -> 0
DA76: =D76 -> 0
DA77: =D77 -> 0
DA78: =D78 -> 0
DA79: =D79 -> 0
DA80: =D80 -> 0
DA81: =D81 -> 0
DA82: =D82 -> 0
DA83: =D83 -> 0
DA84: =D84 -> 0
DA85: =D85 -> 0
DA86: =D86 -> 0
... DA667: =D667 -> 0

Sheet  selon formule
E1: BARRETT | F1: =COUNTIF(donnée!BN:BN,"barrett") -> 0
E2: HAIGIS | F2: =COUNTIF(donnée!BN:BN,"haigis") -> 0
E3: SRK/T | F3: =COUNTIF(donnée!BN:BN,"SRK/T") -> 0
E4: Zeiss | F4: =COUNTIF(donnée!BN:BN,"Zeiss") -> 0
E5: Cooke k6 | F5: =COUNTIF(donnée!BN:BN,"Cooke k6") -> 0
E6: EVO | F6: =COUNTIF(donnée!BN:BN,"EVO") -> 0
E7: Hill-RBF | F7: =COUNTIF(donnée!BN:BN,"HILL-RBF") -> 0
E8: Hoffer QST | F8: =COUNTIF(donnée!BN:BN,"Hoofer QST") -> 0
E9: Kane | F9: =COUNTIF(donnée!BN:BN,"KANE") -> 0
E10: Pearl DGS | F10: =COUNTIF(donnée!BN:BN,"Pearl DGS") -> 0

Sheet  selon Dptr et formule
K1: formule | L1: >+1,0 | M1: +1,0 à +0,76 | N1: +0,75 à +0,51 | O1: +0,50 à +0,26 | P1: +0,25 à -0,25 | Q1: -0,26 à -0,50 | R1: -0,51 à -0,75 | S1: -0,76 -1,0 | T1: > -1,0 | U1: chiffre en pourcentage
K2: BARRETT | L2: =B6*100 -> #DIV/0! | M2: =B7*100 -> #DIV/0! | N2: =B8*100 -> #DIV/0! | O2: =B9*100 -> #DIV/0! | P2: =B10*100 -> #DIV/0! | Q2: =B11*100 -> #DIV/0! | R2: =B12*100 -> #DIV/0! | S2: =B13*100 -> #DIV/0! | T2: =B14*100 -> #DIV/0!
K3: HAIGIS | L3: =B18*100 -> #DIV/0! | M3: =B19*100 -> #DIV/0! | N3: =B20*100 -> #DIV/0! | O3: =B21*100 -> #DIV/0! | P3: =B22*100 -> #DIV/0! | Q3: =B23*100 -> #DIV/0! | R3: =B24*100 -> #DIV/0! | S3: =B25*100 -> #DIV/0! | T3: =B26*100 -> #DIV/0!
A4: resultat BARRETTE | K4: SRK/T | L4: =B30*100 -> #DIV/0! | M4: =B31*100 -> #DIV/0! | N4: =B32*100 -> #DIV/0! | O4: =B33*100 -> #DIV/0! | P4: =B34*100 -> #DIV/0! | Q4: =B35*100 -> #DIV/0! | R4: =B36*100 -> #DIV/0! | S4: =B37*100 -> #DIV/0! | T4: =B38*100 -> #DIV/0!
K5: zeiss | L5: =B42*100 -> #DIV/0! | M5: =B43*100 -> #DIV/0! | N5: =B44*100 -> #DIV/0! | O5: =B45*100 -> #DIV/0! | P5: =B46*100 -> #DIV/0! | Q5: =B47*100 -> #DIV/0! | R5: =B48*100 -> #DIV/0! | S5: =B49*100 -> #DIV/0! | T5: =B50*100 -> #DIV/0!
A6: >+1,0 | B6: =C6/C15 -> #DIV/0! | C6: =COUNTIFS(donnée!AK:AK,">=1,0") -> 0 | K6: Cooke K6 | L6: =B54*100 -> #DIV/0! | M6: =B55*100 -> #DIV/0! | N6: =B56*100 -> #DIV/0! | O6: =B57*100 -> #DIV/0! | P6: =B58*100 -> #DIV/0! | Q6: =B59*100 -> #DIV/0! | R6: =B60*100 -> #DIV/0! | S6: =B61*100 -> #DIV/0! | T6: =B62*100 -> #DIV/0!
A7: +1,0 à +0,76 | B7: =C7/(C15) -> #DIV/0! | C7: =COUNTIFS(donnée!AK:AK,">=0,76",donnée!AK:AK,"<=1,0") -> 0 | K7: EVO | L7: =B66*100 -> #DIV/0! | M7: =B67*100 -> #DIV/0! | N7: =B68*100 -> #DIV/0! | O7: =B69*100 -> #DIV/0! | P7: =B70*100 -> #DIV/0! | Q7: =B71*100 -> #DIV/0! | R7: =B72*100 -> #DIV/0! | S7: =B73*100 -> #DIV/0! | T7: =B74*100 -> #DIV/0!
A8: +0,75 à +0,51 | B8: =C8/(C15) -> #DIV/0! | C8: =COUNTIFS(donnée!AK:AK,">=+0,51",donnée!AK:AK,"<=+0,75") -> 0 | K8: Hill-RBF | L8: =B78*100 -> #DIV/0! | M8: =B79*100 -> #DIV/0! | N8: =B80*100 -> #DIV/0! | O8: =B81*100 -> #DIV/0! | P8: =B82*100 -> #DIV/0! | Q8: =B83*100 -> #DIV/0! | R8: =B84*100 -> #DIV/0! | S8: =B85*100 -> #DIV/0! | T8: =B86*100 -> #DIV/0!
A9: +0,50 à +0,26 | B9: =C9/(C15) -> #DIV/0! | C9: =COUNTIFS(donnée!AK:AK,">=+0,26",donnée!AK:AK,"<=+0,50") -> 0 | K9: Hoffer QST | L9: =B90*100 -> #DIV/0! | M9: =B91*100 -> #DIV/0! | N9: =B92*100 -> #DIV/0! | O9: =B93*100 -> #DIV/0! | P9: =B94*100 -> #DIV/0! | Q9: =B95*100 -> #DIV/0! | R9: =B96*100 -> #DIV/0! | S9: =B97*100 -> #DIV/0! | T9: =B98*100 -> #DIV/0!
A10: +0,25 à -0,25 | B10: =C10/(C15) -> #DIV/0! | C10: =COUNTIFS(donnée!AK:AK,">=-0,25",donnée!AK:AK,"<=+0,25") -> 0 | K10: Kane | L10: =C102*100 -> 0 | M10: =C103*100 -> 0 | N10: =C104*100 -> 0 | O10: =C105*100 -> 0 | P10: =C106*100 -> 0 | Q10: =C107*100 -> 0 | R10: =C108*100 -> 0 | S10: =C109*100 -> 0 | T10: =C110*100 -> 0
A11: -0,26 à -0,50 | B11: =C11/(C15) -> #DIV/0! | C11: =COUNTIFS(donnée!AK:AK,">=-0,50",donnée!AK:AK,"<=-0,26") -> 0 | K11: Pearl DGS | L11: =B114*100 -> #DIV/0! | M11: =B115*100 -> #DIV/0! | N11: =B116*100 -> #DIV/0! | O11: =B117*100 -> #DIV/0! | P11: =B118*100 -> #DIV/0! | Q11: =B119*100 -> #DIV/0! | R11: =B120*100 -> #DIV/0! | S11: =B121*100 -> #DIV/0! | T11: =B122*100 -> #DIV/0!
A12: -0,51 à -0,75 | B12: =C12/(C15) -> #DIV/0! | C12: =COUNTIFS(donnée!AK:AK,">=-0,75",donnée!AK:AK,"<=-0,51") -> 0
A13: -0,76 -1,0 | B13: =C13/(C15) -> #DIV/0! | C13: =COUNTIFS(donnée!AK:AK,">=-1,0",donnée!AK:AK,"<=-0,76") -> 0
A14: > -1,0 | B14: =C14/(C15) -> #DIV/0! | C14: =COUNTIFS(donnée!AK:AK,"<=-1,0") -> 0
A15: total | B15: =SUM(B6:B14) -> #DIV/0! | C15: =SUM(C6:C14) -> 0
A16: resultat HAIGIS
A18: >+1,0 | B18: =C18/(C27) -> #DIV/0! | C18: =COUNTIFS(donnée!AN:AN,">=1,0") -> 0
A19: +1,0 à +0,76 | B19: =C19/(C27) -> #DIV/0! | C19: =COUNTIFS(donnée!AN:AN,">=0,76",donnée!AN:AN,"<=1,0") -> 0
A20: +0,75 à +0,51 | B20: =C20/(C27) -> #DIV/0! | C20: =COUNTIFS(donnée!AN:AN,">=+0,51",donnée!AN:AN,"<=+0,75") -> 0
A21: +0,50 à +0,26 | B21: =C21/(C27) -> #DIV/0! | C21: =COUNTIFS(donnée!AN:AN,">=+0,26",donnée!AN:AN,"<=+0,50") -> 0
A22: +0,25 à -0,25 | B22: =C22/(C27) -> #DIV/0! | C22: =COUNTIFS(donnée!AN:AN,">=-0,25",donnée!AN:AN,"<=+0,25") -> 0
A23: -0,26 à -0,50 | B23: =C23/(C27) -> #DIV/0! | C23: =COUNTIFS(donnée!AN:AN,">=-0,50",donnée!AN:AN,"<=-0,26") -> 0
A24: -0,51 à -0,75 | B24: =C24/(C27) -> #DIV/0! | C24: =COUNTIFS(donnée!AN:AN,">=-0,75",donnée!AN:AN,"<=-0,51") -> 0
A25: -0,76 -1,0 | B25: =C25/(C27) -> #DIV/0! | C25: =COUNTIFS(donnée!AN:AN,">=-1,0",donnée!AN:AN,"<=-0,76") -> 0
A26: > -1,0 | B26: =C26/(C27) -> #DIV/0! | C26: =COUNTIFS(donnée!AN:AN,"<=-1,0") -> 0
A27: total | B27: =SUM(B18:B26) -> #DIV/0! | C27: =SUM(C18:C26) -> 0
A28: resultat SRK/T
A30: >+1,0 | B30: =C30/(C39) -> #DIV/0! | C30: =COUNTIFS(donnée!AQ:AQ,">=1,0") -> 0
A31: +1,0 à +0,76 | B31: =C31/(C39) -> #DIV/0! | C31: =COUNTIFS(donnée!AQ:AQ,">=0,76",donnée!AQ:AQ,"<=1,0") -> 0
A32: +0,75 à +0,51 | B32: =C32/(C39) -> #DIV/0! | C32: =COUNTIFS(donnée!AQ:AQ,">=+0,51",donnée!AQ:AQ,"<=+0,75") -> 0
A33: +0,50 à +0,26 | B33: =C33/(C39) -> #DIV/0! | C33: =COUNTIFS(donnée!AQ:AQ,">=+0,26",donnée!AQ:AQ,"<=+0,50") -> 0
A34: +0,25 à -0,25 | B34: =C34/(C39) -> #DIV/0! | C34: =COUNTIFS(donnée!AQ:AQ,">=-0,25",donnée!AQ:AQ,"<=+0,25") -> 0
A35: -0,26 à -0,50 | B35: =C35/(C39) -> #DIV/0! | C35: =COUNTIFS(donnée!AQ:AQ,">=-0,50",donnée!AQ:AQ,"<=-0,26") -> 0
A36: -0,51 à -0,75 | B36: =C36/(C39) -> #DIV/0! | C36: =COUNTIFS(donnée!AQ:AQ,">=-0,75",donnée!AQ:AQ,"<=-0,51") -> 0
A37: -0,76 -1,0 | B37: =C37/(C39) -> #DIV/0! | C37: =COUNTIFS(donnée!AQ:AQ,">=-1,0",donnée!AQ:AQ,"<=-0,76") -> 0
A38: > -1,0 | B38: =C38/(C39) -> #DIV/0! | C38: =COUNTIFS(donnée!AQ:AQ,"<=-1,0") -> 0
A39: total | B39: =SUM(B30:B38) -> #DIV/0! | C39: =SUM(C30:C38) -> 0
A40: resultat Zeiss
A42: >+1,0 | B42: =C42/(C51) -> #DIV/0! | C42: =COUNTIFS(donnée!AT:AT,">=1,0") -> 0
A43: +1,0 à +0,76 | B43: =C43/(C51) -> #DIV/0! | C43: =COUNTIFS(donnée!AT:AT,">=0,76",donnée!AT:AT,"<=1,0") -> 0
...

Sheet  typ oeil  formulle
C2: PUISSANCE IOL =>30 | D2: PUISSANCE IOL 30 => 25 | E2: PUISSANCE IOL 25 => 15 | F2: PUISSANCE IOL 15 => 10 | G2: PUISSANCE IOL 10 => 0 | H2: PUISSANCE IOL 0=> | J2: œil extrème >28mm | K2: Œil très long 28>26 | L2: Œil long 26>24,5 | M2: Œil long NORMAL 24,5>22,5 | N2: Œil court 22,5>20 | O2: Œil très court <20 | Q2: K extrème >48,5 | R2: K CAMBRE 48,5>46,5 | S2: K CAMBRE- 46,5>45 | T2: K NORM 45>43 | U2: K PLAT- 43>41 | V2: K PLAT >41,0 | X2: CA extrème >4,0 | Y2: CA profonde 4>3,5 | Z2: CA NORM 3,5>2,5 | AA2: CA ETROITE 2,5>2,0 | AB2: CA tres etroite <2,0 | AE2: LT TRES EPAIS >5,3 | AF2: LT EPAIS 5,3>4,9 | AG2: LT NORMAL 4,9>3,8 | AH2: LT FIN>3,8 | AL2: WTW EXTREME >13 | AM2: WTW GRAND 13>12,5 | AN2: WTW NORM 12,5>11,5 | AO2: WTW PETITE <11,5 | AS2: AGE +90 | AT2: AGE 89 => 80 | AU2: AGE 80 => 70 | AV2: AGE 69 => 60 | AW2: AGE 59 => 50 | AX2: AGE 49 => 40 | AY2: AGE -39
B3: BARRETTE | I3: BARRETTE | P3: BARRETTE | W3: BARRETTE | AD3: BARRETTE | AK3: BARRETTE | AR3: BARRETTE
B4: >+1,0 | C4: =COUNTIFS(donnée!AK:AK,">=1,0",donnée!BO:BO,"oui") -> 0 | D4: =COUNTIFS(donnée!AK:AK,">=1,0",donnée!BP:BP,"oui") -> 0 | E4: =COUNTIFS(donnée!AK:AK,">=1,0",donnée!BQ:BQ,"oui") -> 0 | F4: =COUNTIFS(donnée!AK:AK,">=1,0",donnée!BR:BR,"oui") -> 0 | G4: =COUNTIFS(donnée!AK:AK,">=1,0",donnée!BS:BS,"oui") -> 0 | H4: =COUNTIFS(donnée!AK:AK,">=1,0",donnée!BT:BT,"oui") -> 0 | I4: >+1,0 | J4: =COUNTIFS(donnée!AK:AK,">=1,0",donnée!BU:BU,"oui") -> 0 | K4: =COUNTIFS(donnée!AK:AK,">=1,0",donnée!BV:BV,"oui") -> 0 | L4: =COUNTIFS(donnée!AK:AK,">=1,0",donnée!BW:BW,"oui") -> 0 | M4: =COUNTIFS(donnée!AK:AK,">=1,0",donnée!BX:BX,"oui") -> 0 | N4: =COUNTIFS(donnée!AK:AK,">=1,0",donnée!BY:BY,"oui") -> 0 | O4: =COUNTIFS(donnée!AK:AK,">=1,0",donnée!BZ:BZ,"oui") -> 0 | P4: >+1,0 | Q4: =COUNTIFS(donnée!AK:AK,">=1,0",donnée!CA:CA,"oui") -> 0 | R4: =COUNTIFS(donnée!AK:AK,">=1,0",donnée!CB:CB,"oui") -> 0 | S4: =COUNTIFS(donnée!AK:AK,">=1,0",donnée!CC:CC,"oui") -> 0 | T4: =COUNTIFS(donnée!AK:AK,">=1,0",donnée!CD:CD,"oui") -> 0 | U4: =COUNTIFS(donnée!AK:AK,">=1,0",donnée!CE:CE,"oui") -> 0 | V4: =COUNTIFS(donnée!AK:AK,">=1,0",donnée!CF:CF,"oui") -> 0 | W4: >+1,0 | X4: =COUNTIFS(donnée!AK:AK,">=1,0",donnée!CG:CG,"oui") -> 0 | Y4: =COUNTIFS(donnée!AK:AK,">=1,0",donnée!CH:CH,"oui") -> 0 | Z4: =COUNTIFS(donnée!AK:AK,">=1,0",donnée!CI:CI,"oui") -> 0 | AA4: =COUNTIFS(donnée!AK:AK,">=1,0",donnée!CJ:CJ,"oui") -> 0 | AB4: =COUNTIFS(donnée!AK:AK,">=1,0",donnée!CK:CK,"oui") -> 0 | AD4: >+1,0 | AE4: =COUNTIFS(donnée!AK:AK,">=1,0",donnée!CL:CL,"oui") -> 0 | AF4: =COUNTIFS(donnée!AK:AK,">=1,0",donnée!CM:CM,"oui") -> 0 | AG4: =COUNTIFS(donnée!AK:AK,">=1,0",donnée!CN:CN,"oui") -> 0 | AH4: =COUNTIFS(donnée!AK:AK,">=1,0",donnée!CO:CO,"oui") -> 0 | AK4: >+1,0 | AL4: =COUNTIFS(donnée!AK:AK,">=1,0",donnée!CP:CP,"oui") -> 0 | AM4: =COUNTIFS(donnée!AK:AK,">=1,0",donnée!CQ:CQ,"oui") -> 0 | AN4: =COUNTIFS(donnée!AK:AK,">=1,0",donnée!CR:CR,"oui") -> 0 | AO4: =COUNTIFS(donnée!AK:AK,">=1,0",donnée!CS:CS,"oui") -> 0 | AR4: >+1,0 | AS4: =COUNTIFS(donnée!AK:AK,">=1,0",donnée!CT:CT,"oui") -> 0 | AT4: =COUNTIFS(donnée!AK:AK,">=1,0",donnée!CU:CU,"oui") -> 0 | AU4: =COUNTIFS(donnée!AK:AK,">=1,0",donnée!CV:CV,"oui") -> 0 | AV4: =COUNTIFS(donnée!AK:AK,">=1,0",donnée!CW:CW,"oui") -> 0 | AW4: =COUNTIFS(donnée!AK:AK,">=1,0",donnée!CX:CX,"oui") -> 0 | AX4: =COUNTIFS(donnée!AK:AK,">=1,0",donnée!CY:CY,"oui") -> 0 | AY4: =COUNTIFS(donnée!AK:AK,">=1,0",donnée!CZ:CZ,"oui") -> 0
B5: +1,0 à +0,76 | C5: =COUNTIFS(donnée!AK:AK,">=0,76",donnée!AK:AK,"<=1,0",donnée!BO:BO,"oui") -> 0 | D5: =COUNTIFS(donnée!AK:AK,">=0,76",donnée!AK:AK,"<=1,0",donnée!BP:BP,"oui") -> 0 | E5: =COUNTIFS(donnée!AK:AK,">=0,76",donnée!AK:AK,"<=1,0",donnée!BQ:BQ,"oui") -> 0 | F5: =COUNTIFS(donnée!AK:AK,">=0,76",donnée!AK:AK,"<=1,0",donnée!BR:BR,"oui") -> 0 | G5: =COUNTIFS(donnée!AK:AK,">=0,76",donnée!AK:AK,"<=1,0",donnée!BS:BS,"oui") -> 0 | H5: =COUNTIFS(donnée!AK:AK,">=0,76",donnée!AK:AK,"<=1,0",donnée!BT:BT,"oui") -> 0 | I5: +1,0 à +0,76 | J5: =COUNTIFS(donnée!AK:AK,">=0,76",donnée!AK:AK,"<=1,0",donnée!BU:BU,"oui") -> 0 | K5: =COUNTIFS(donnée!AK:AK,">=0,76",donnée!AK:AK,"<=1,0",donnée!BV:BV,"oui") -> 0 | L5: =COUNTIFS(donnée!AK:AK,">=0,76",donnée!AK:AK,"<=1,0",donnée!BW:BW,"oui") -> 0 | M5: =COUNTIFS(donnée!AK:AK,">=0,76",donnée!AK:AK,"<=1,0",donnée!BX:BX,"oui") -> 0 | N5: =COUNTIFS(donnée!AK:AK,">=0,76",donnée!AK:AK,"<=1,0",donnée!BY:BY,"oui") -> 0 | O5: =COUNTIFS(donnée!AK:AK,">=0,76",donnée!AK:AK,"<=1,0",donnée!BZ:BZ,"oui") -> 0 | P5: +1,0 à +0,76 | Q5: =COUNTIFS(donnée!AK:AK,">=0,76",donnée!AK:AK,"<=1,0",donnée!CA:CA,"oui") -> 0 | R5: =COUNTIFS(donnée!AK:AK,">=0,76",donnée!AK:AK,"<=1,0",donnée!CB:CB,"oui") -> 0 | S5: =COUNTIFS(donnée!AK:AK,">=0,76",donnée!AK:AK,"<=1,0",donnée!CC:CC,"oui") -> 0 | T5: =COUNTIFS(donnée!AK:AK,">=0,76",donnée!AK:AK,"<=1,0",donnée!CD:CD,"oui") -> 0 | U5: =COUNTIFS(donnée!AK:AK,">=0,76",donnée!AK:AK,"<=1,0",donnée!CE:CE,"oui") -> 0 | V5: =COUNTIFS(donnée!AK:AK,">=0,76",donnée!AK:AK,"<=1,0",donnée!CF:CF,"oui") -> 0 | W5: +1,0 à +0,76 | X5: =COUNTIFS(donnée!AK:AK,">=0,76",donnée!AK:AK,"<=1,0",donnée!CG:CG,"oui") -> 0 | Y5: =COUNTIFS(donnée!AK:AK,">=0,76",donnée!AK:AK,"<=1,0",donnée!CH:CH,"oui") -> 0 | Z5: =COUNTIFS(donnée!AK:AK,">=0,76",donnée!AK:AK,"<=1,0",donnée!CI:CI,"oui") -> 0 | AA5: =COUNTIFS(donnée!AK:AK,">=0,76",donnée!AK:AK,"<=1,0",donnée!CJ:CJ,"oui") -> 0 | AB5: =COUNTIFS(donnée!AK:AK,">=0,76",donnée!AK:AK,"<=1,0",donnée!CK:CK,"oui") -> 0 | AD5: +1,0 à +0,76 | AE5: =COUNTIFS(donnée!AK:AK,">=0,76",donnée!AK:AK,"<=1,0",donnée!CL:CL,"oui") -> 0 | AF5: =COUNTIFS(donnée!AK:AK,">=0,76",donnée!AK:AK,"<=1,0",donnée!CM:CM,"oui") -> 0 | AG5: =COUNTIFS(donnée!AK:AK,">=0,76",donnée!AK:AK,"<=1,0",donnée!CN:CN,"oui") -> 0 | AH5: =COUNTIFS(donnée!AK:AK,">=0,76",donnée!AK:AK,"<=1,0",donnée!CO:CO,"oui") -> 0 | AK5: +1,0 à +0,76 | AL5: =COUNTIFS(donnée!AK:AK,">=0,76",donnée!AK:AK,"<=1,0",donnée!CP:CP,"oui") -> 0 | AM5: =COUNTIFS(donnée!AK:AK,">=0,76",donnée!AK:AK,"<=1,0",donnée!CQ:CQ,"oui") -> 0 | AN5: =COUNTIFS(donnée!AK:AK,">=0,76",donnée!AK:AK,"<=1,0",donnée!CR:CR,"oui") -> 0 | AO5: =COUNTIFS(donnée!AK:AK,">=0,76",donnée!AK:AK,"<=1,0",donnée!CS:CS,"oui") -> 0 | AR5: +1,0 à +0,76 | AS5: =COUNTIFS(donnée!AK:AK,">=0,76",donnée!AK:AK,"<=1,0",donnée!CT:CT,"oui") -> 0 | AT5: =COUNTIFS(donnée!AK:AK,">=0,76",donnée!AK:AK,"<=1,0",donnée!CU:CU,"oui") -> 0 | AU5: =COUNTIFS(donnée!AK:AK,">=0,76",donnée!AK:AK,"<=1,0",donnée!CV:CV,"oui") -> 0 | AV5: =COUNTIFS(donnée!AK:AK,">=0,76",donnée!AK:AK,"<=1,0",donnée!CW:CW,"oui") -> 0 | AW5: =COUNTIFS(donnée!AK:AK,">=0,76",donnée!AK:AK,"<=1,0",donnée!CX:CX,"oui") -> 0 | AX5: =COUNTIFS(donnée!AK:AK,">=0,76",donnée!AK:AK,"<=1,0",donnée!CY:CY,"oui") -> 0 | AY5: =COUNTIFS(donnée!AK:AK,">=0,76",donnée!AK:AK,"<=1,0",donnée!CZ:CZ,"oui") -> 0
B6: +0,75 à +0,51 | C6: =COUNTIFS(donnée!AK:AK,">=+0,51",donnée!AK:AK,"<=+0,75",donnée!BO:BO,"oui") -> 0 | D6: =COUNTIFS(donnée!AK:AK,">=+0,51",donnée!AK:AK,"<=+0,75",donnée!BP:BP,"oui") -> 0 | E6: =COUNTIFS(donnée!AK:AK,">=+0,51",donnée!AK:AK,"<=+0,75",donnée!BQ:BQ,"oui") -> 0 | F6: =COUNTIFS(donnée!AK:AK,">=+0,51",donnée!AK:AK,"<=+0,75",donnée!BR:BR,"oui") -> 0 | G6: =COUNTIFS(donnée!AK:AK,">=+0,51",donnée!AK:AK,"<=+0,75",donnée!BS:BS,"oui") -> 0 | H6: =COUNTIFS(donnée!AK:AK,">=+0,51",donnée!AK:AK,"<=+0,75",donnée!BT:BT,"oui") -> 0 | I6: +0,75 à +0,51 | J6: =COUNTIFS(donnée!AK:AK,">=+0,51",donnée!AK:AK,"<=+0,75",donnée!BU:BU,"oui") -> 0 | K6: =COUNTIFS(donnée!AK:AK,">=+0,51",donnée!AK:AK,"<=+0,75",donnée!BV:BV,"oui") -> 0 | L6: =COUNTIFS(donnée!AK:AK,">=+0,51",donnée!AK:AK,"<=+0,75",donnée!BW:BW,"oui") -> 0 | M6: =COUNTIFS(donnée!AK:AK,">=+0,51",donnée!AK:AK,"<=+0,75",donnée!BX:BX,"oui") -> 0 | N6: =COUNTIFS(donnée!AK:AK,">=+0,51",donnée!AK:AK,"<=+0,75",donnée!BY:BY,"oui") -> 0 | O6: =COUNTIFS(donnée!AK:AK,">=+0,51",donnée!AK:AK,"<=+0,75",donnée!BZ:BZ,"oui") -> 0 | P6: +0,75 à +0,51 | Q6: =COUNTIFS(donnée!AK:AK,">=+0,51",donnée!AK:AK,"<=+0,75",donnée!CA:CA,"oui") -> 0 | R6: =COUNTIFS(donnée!AK:AK,">=+0,51",donnée!AK:AK,"<=+0,75",donnée!CB:CB,"oui") -> 0 | S6: =COUNTIFS(donnée!AM:AM,">=+0,51",donnée!AM:AM,"<=+0,75",donnée!CC:CC,"oui") -> 0 | T6: =COUNTIFS(donnée!AK:AK,">=+0,51",donnée!AK:AK,"<=+0,75",donnée!CD:CD,"oui") -> 0 | U6: =COUNTIFS(donnée!AK:AK,">=+0,51",donnée!AK:AK,"<=+0,75",donnée!CE:CE,"oui") -> 0 | V6: =COUNTIFS(donnée!AK:AK,">=+0,51",donnée!AK:AK,"<=+0,75",donnée!CF:CF,"oui") -> 0 | W6: +0,75 à +0,51 | X6: =COUNTIFS(donnée!AK:AK,">=+0,51",donnée!AK:AK,"<=+0,75",donnée!CG:CG,"oui") -> 0 | Y6: =COUNTIFS(donnée!AK:AK,">=+0,51",donnée!AK:AK,"<=+0,75",donnée!CH:CH,"oui") -> 0 | Z6: =COUNTIFS(donnée!AK:AK,">=+0,51",donnée!AK:AK,"<=+0,75",donnée!CI:CI,"oui") -> 0 | AA6: =COUNTIFS(donnée!AK:AK,">=+0,51",donnée!AK:AK,"<=+0,75",donnée!CJ:CJ,"oui") -> 0 | AB6: =COUNTIFS(donnée!AK:AK,">=+0,51",donnée!AK:AK,"<=+0,75",donnée!CK:CK,"oui") -> 0 | AD6: +0,75 à +0,51 | AE6: =COUNTIFS(donnée!AK:AK,">=+0,51",donnée!AK:AK,"<=+0,75",donnée!CL:CL,"oui") -> 0 | AF6: =COUNTIFS(donnée!AK:AK,">=+0,51",donnée!AK:AK,"<=+0,75",donnée!CM:CM,"oui") -> 0 | AG6: =COUNTIFS(donnée!AK:AK,">=+0,51",donnée!AK:AK,"<=+0,75",donnée!CN:CN,"oui") -> 0 | AH6: =COUNTIFS(donnée!AK:AK,">=+0,51",donnée!AK:AK,"<=+0,75",donnée!CO:CO,"oui") -> 0 | AK6: +0,75 à +0,51 | AL6: =COUNTIFS(donnée!AK:AK,">=+0,51",donnée!AK:AK,"<=+0,75",donnée!CP:CP,"oui") -> 0 | AM6: =COUNTIFS(donnée!AK:AK,">=+0,51",donnée!AK:AK,"<=+0,75",donnée!CQ:CQ,"oui") -> 0 | AN6: =COUNTIFS(donnée!AK:AK,">=+0,51",donnée!AK:AK,"<=+0,75",donnée!CR:CR,"oui") -> 0 | AO6: =COUNTIFS(donnée!AK:AK,">=+0,51",donnée!AK:AK,"<=+0,75",donnée!CS:CS,"oui") -> 0 | AR6: +0,75 à +0,51 | AS6: =COUNTIFS(donnée!AK:AK,">=+0,51",donnée!AK:AK,"<=+0,75",donnée!CT:CT,"oui") -> 0 | AT6: =COUNTIFS(donnée!AK:AK,">=+0,51",donnée!AK:AK,"<=+0,75",donnée!CU:CU,"oui") -> 0 | AU6: =COUNTIFS(donnée!AK:AK,">=+0,51",donnée!AK:AK,"<=+0,75",donnée!CV:CV,"oui") -> 0 | AV6: =COUNTIFS(donnée!AK:AK,">=+0,51",donnée!AK:AK,"<=+0,75",donnée!CW:CW,"oui") -> 0 | AW6: =COUNTIFS(donnée!AK:AK,">=+0,51",donnée!AK:AK,"<=+0,75",donnée!CX:CX,"oui") -> 0 | AX6: =COUNTIFS(donnée!AK:AK,">=+0,51",donnée!AK:AK,"<=+0,75",donnée!CY:CY,"oui") -> 0 | AY6: =COUNTIFS(donnée!AK:AK,">=+0,51",donnée!AK:AK,"<=+0,75",donnée!CZ:CZ,"oui") -> 0
B7: +0,50 à +0,26 | C7: =COUNTIFS(donnée!AK:AK,">=+0,26",donnée!AK:AK,"<=+0,50",donnée!BO:BO,"oui") -> 0 | D7: =COUNTIFS(donnée!AK:AK,">=+0,26",donnée!AK:AK,"<=+0,50",donnée!BP:BP,"oui") -> 0 | E7: =COUNTIFS(donnée!AK:AK,">=+0,26",donnée!AK:AK,"<=+0,50",donnée!BQ:BQ,"oui") -> 0 | F7: =COUNTIFS(donnée!AK:AK,">=+0,26",donnée!AK:AK,"<=+0,50",donnée!BR:BR,"oui") -> 0 | G7: =COUNTIFS(donnée!AK:AK,">=+0,26",donnée!AK:AK,"<=+0,50",donnée!BS:BS,"oui") -> 0 | H7: =COUNTIFS(donnée!AK:AK,">=+0,26",donnée!AK:AK,"<=+0,50",donnée!BT:BT,"oui") -> 0 | I7: +0,50 à +0,26 | J7: =COUNTIFS(donnée!AK:AK,">=+0,26",donnée!AK:AK,"<=+0,50",donnée!BU:BU,"oui") -> 0 | K7: =COUNTIFS(donnée!AK:AK,">=+0,26",donnée!AK:AK,"<=+0,50",donnée!BV:BV,"oui") -> 0 | L7: =COUNTIFS(donnée!AK:AK,">=+0,26",donnée!AK:AK,"<=+0,50",donnée!BW:BW,"oui") -> 0 | M7: =COUNTIFS(donnée!AK:AK,">=+0,26",donnée!AK:AK,"<=+0,50",donnée!BX:BX,"oui") -> 0 | N7: =COUNTIFS(donnée!AK:AK,">=+0,26",donnée!AK:AK,"<=+0,50",donnée!BY:BY,"oui") -> 0 | O7: =COUNTIFS(donnée!AK:AK,">=+0,26",donnée!AK:AK,"<=+0,50",donnée!BZ:BZ,"oui") -> 0 | P7: +0,50 à +0,26 | Q7: =COUNTIFS(donnée!AK:AK,">=+0,26",donnée!AK:AK,"<=+0,50",donnée!CA:CA,"oui") -> 0 | R7: =COUNTIFS(donnée!AK:AK,">=+0,26",donnée!AK:AK,"<=+0,50",donnée!CB:CB,"oui") -> 0 | S7: =COUNTIFS(donnée!AK:AK,">=+0,26",donnée!AK:AK,"<=+0,50",donnée!CC:CC,"oui") -> 0 | T7: =COUNTIFS(donnée!AK:AK,">=+0,26",donnée!AK:AK,"<=+0,50",donnée!CD:CD,"oui") -> 0 | U7: =COUNTIFS(donnée!AK:AK,">=+0,26",donnée!AK:AK,"<=+0,50",donnée!CE:CE,"oui") -> 0 | V7: =COUNTIFS(donnée!AK:AK,">=+0,26",donnée!AK:AK,"<=+0,50",donnée!CF:CF,"oui") -> 0 | W7: +0,50 à +0,26 | X7: =COUNTIFS(donnée!AK:AK,">=+0,26",donnée!AK:AK,"<=+0,50",donnée!CG:CG,"oui") -> 0 | Y7: =COUNTIFS(donnée!AK:AK,">=+0,26",donnée!AK:AK,"<=+0,50",donnée!CH:CH,"oui") -> 0 | Z7: =COUNTIFS(donnée!AK:AK,">=+0,26",donnée!AK:AK,"<=+0,50",donnée!CI:CI,"oui") -> 0 | AA7: =COUNTIFS(donnée!AK:AK,">=+0,26",donnée!AK:AK,"<=+0,50",donnée!CJ:CJ,"oui") -> 0 | AB7: =COUNTIFS(donnée!AK:AK,">=+0,26",donnée!AK:AK,"<=+0,50",donnée!CK:CK,"oui") -> 0 | AD7: +0,50 à +0,26 | AE7: =COUNTIFS(donnée!AK:AK,">=+0,26",donnée!AK:AK,"<=+0,50",donnée!CL:CL,"oui") -> 0 | AF7: =COUNTIFS(donnée!AK:AK,">=+0,26",donnée!AK:AK,"<=+0,50",donnée!CM:CM,"oui") -> 0 | AG7: =COUNTIFS(donnée!AK:AK,">=+0,26",donnée!AK:AK,"<=+0,50",donnée!CN:CN,"oui") -> 0 | AH7: =COUNTIFS(donnée!AK:AK,">=+0,26",donnée!AK:AK,"<=+0,50",donnée!CO:CO,"oui") -> 0 | AK7: +0,50 à +0,26 | AL7: =COUNTIFS(donnée!AK:AK,">=+0,26",donnée!AK:AK,"<=+0,50",donnée!CP:CP,"oui") -> 0 | AM7: =COUNTIFS(donnée!AK:AK,">=+0,26",donnée!AK:AK,"<=+0,50",donnée!CQ:CQ,"oui") -> 0 | AN7: =COUNTIFS(donnée!AK:AK,">=+0,26",donnée!AK:AK,"<=+0,50",donnée!CR:CR,"oui") -> 0 | AO7: =COUNTIFS(donnée!AK:AK,">=+0,26",donnée!AK:AK,"<=+0,50",donnée!CS:CS,"oui") -> 0 | AR7: +0,50 à +0,26 | AS7: =COUNTIFS(donnée!AK:AK,">=+0,26",donnée!AK:AK,"<=+0,50",donnée!CT:CT,"oui") -> 0 | AT7: =COUNTIFS(donnée!AK:AK,">=+0,26",donnée!AK:AK,"<=+0,50",donnée!CU:CU,"oui") -> 0 | AU7: =COUNTIFS(donnée!AK:AK,">=+0,26",donnée!AK:AK,"<=+0,50",donnée!CV:CV,"oui") -> 0 | AV7: =COUNTIFS(donnée!AK:AK,">=+0,26",donnée!AK:AK,"<=+0,50",donnée!CW:CW,"oui") -> 0 | AW7: =COUNTIFS(donnée!AK:AK,">=+0,26",donnée!AK:AK,"<=+0,50",donnée!CX:CX,"oui") -> 0 | AX7: =COUNTIFS(donnée!AK:AK,">=+0,26",donnée!AK:AK,"<=+0,50",donnée!CY:CY,"oui") -> 0 | AY7: =COUNTIFS(donnée!AK:AK,">=+0,26",donnée!AK:AK,"<=+0,50",donnée!CZ:CZ,"oui") -> 0
B8: +0,25 à -0,25 | C8: =COUNTIFS(donnée!AK:AK,">=-0,25",donnée!AK:AK,"<=+0,25",donnée!BO:BO,"oui") -> 0 | D8: =COUNTIFS(donnée!AK:AK,">=-0,25",donnée!AK:AK,"<=+0,25",donnée!BP:BP,"oui") -> 0 | E8: =COUNTIFS(donnée!AK:AK,">=-0,25",donnée!AK:AK,"<=+0,25",donnée!BQ:BQ,"oui") -> 0 | F8: =COUNTIFS(donnée!AK:AK,">=-0,25",donnée!AK:AK,"<=+0,25",donnée!BR:BR,"oui") -> 0 | G8: =COUNTIFS(donnée!AK:AK,">=-0,25",donnée!AK:AK,"<=+0,25",donnée!BS:BS,"oui") -> 0 | H8: =COUNTIFS(donnée!AK:AK,">=-0,25",donnée!AK:AK,"<=+0,25",donnée!BT:BT,"oui") -> 0 | I8: +0,25 à -0,25 | J8: =COUNTIFS(donnée!AK:AK,">=-0,25",donnée!AK:AK,"<=+0,25",donnée!BU:BU,"oui") -> 0 | K8: =COUNTIFS(donnée!AK:AK,">=-0,25",donnée!AK:AK,"<=+0,25",donnée!BV:BV,"oui") -> 0 | L8: =COUNTIFS(donnée!AK:AK,">=-0,25",donnée!AK:AK,"<=+0,25",donnée!BW:BW,"oui") -> 0 | M8: =COUNTIFS(donnée!AK:AK,">=-0,25",donnée!AK:AK,"<=+0,25",donnée!BX:BX,"oui") -> 0 | N8: =COUNTIFS(donnée!AK:AK,">=-0,25",donnée!AK:AK,"<=+0,25",donnée!BY:BY,"oui") -> 0 | O8: =COUNTIFS(donnée!AK:AK,">=-0,25",donnée!AK:AK,"<=+0,25",donnée!BZ:BZ,"oui") -> 0 | P8: +0,25 à -0,25 | Q8: =COUNTIFS(donnée!AK:AK,">=-0,25",donnée!AK:AK,"<=+0,25",donnée!CA:CA,"oui") -> 0 | R8: =COUNTIFS(donnée!AK:AK,">=-0,25",donnée!AK:AK,"<=+0,25",donnée!CB:CB,"oui") -> 0 | S8: =COUNTIFS(donnée!AK:AK,">=-0,25",donnée!AK:AK,"<=+0,25",donnée!CC:CC,"oui") -> 0 | T8: =COUNTIFS(donnée!AK:AK,">=-0,25",donnée!AK:AK,"<=+0,25",donnée!CD:CD,"oui") -> 0 | U8: =COUNTIFS(donnée!AK:AK,">=-0,25",donnée!AK:AK,"<=+0,25",donnée!CE:CE,"oui") -> 0 | V8: =COUNTIFS(donnée!AK:AK,">=-0,25",donnée!AK:AK,"<=+0,25",donnée!CF:CF,"oui") -> 0 | W8: +0,25 à -0,25 | X8: =COUNTIFS(donnée!AK:AK,">=-0,25",donnée!AK:AK,"<=+0,25",donnée!CG:CG,"oui") -> 0 | Y8: =COUNTIFS(donnée!AK:AK,">=-0,25",donnée!AK:AK,"<=+0,25",donnée!CH:CH,"oui") -> 0 | Z8: =COUNTIFS(donnée!AK:AK,">=-0,25",donnée!AK:AK,"<=+0,25",donnée!CI:CI,"oui") -> 0 | AA8: =COUNTIFS(donnée!AK:AK,">=-0,25",donnée!AK:AK,"<=+0,25",donnée!CJ:CJ,"oui") -> 0 | AB8: =COUNTIFS(donnée!AK:AK,">=-0,25",donnée!AK:AK,"<=+0,25",donnée!CK:CK,"oui") -> 0 | AD8: +0,25 à -0,25 | AE8: =COUNTIFS(donnée!AK:AK,">=-0,25",donnée!AK:AK,"<=+0,25",donnée!CL:CL,"oui") -> 0 | AF8: =COUNTIFS(donnée!AK:AK,">=-0,25",donnée!AK:AK,"<=+0,25",donnée!CM:CM,"oui") -> 0 | AG8: =COUNTIFS(donnée!AK:AK,">=-0,25",donnée!AK:AK,"<=+0,25",donnée!CN:CN,"oui") -> 0 | AH8: =COUNTIFS(donnée!AK:AK,">=-0,25",donnée!AK:AK,"<=+0,25",donnée!CO:CO,"oui") -> 0 | AK8: +0,25 à -0,25 | AL8: =COUNTIFS(donnée!AK:AK,">=-0,25",donnée!AK:AK,"<=+0,25",donnée!CP:CP,"oui") -> 0 | AM8: =COUNTIFS(donnée!AK:AK,">=-0,25",donnée!AK:AK,"<=+0,25",donnée!CQ:CQ,"oui") -> 0 | AN8: =COUNTIFS(donnée!AK:AK,">=-0,25",donnée!AK:AK,"<=+0,25",donnée!CR:CR,"oui") -> 0 | AO8: =COUNTIFS(donnée!AK:AK,">=-0,25",donnée!AK:AK,"<=+0,25",donnée!CS:CS,"oui") -> 0 | AR8: +0,25 à -0,25 | AS8: =COUNTIFS(donnée!AK:AK,">=-0,25",donnée!AK:AK,"<=+0,25",donnée!CT:CT,"oui") -> 0 | AT8: =COUNTIFS(donnée!AK:AK,">=-0,25",donnée!AK:AK,"<=+0,25",donnée!CU:CU,"oui") -> 0 | AU8: =COUNTIFS(donnée!AK:AK,">=-0,25",donnée!AK:AK,"<=+0,25",donnée!CV:CV,"oui") -> 0 | AV8: =COUNTIFS(donnée!AK:AK,">=-0,25",donnée!AK:AK,"<=+0,25",donnée!CW:CW,"oui") -> 0 | AW8: =COUNTIFS(donnée!AK:AK,">=-0,25",donnée!AK:AK,"<=+0,25",donnée!CX:CX,"oui") -> 0 | AX8: =COUNTIFS(donnée!AK:AK,">=-0,25",donnée!AK:AK,"<=+0,25",donnée!CY:CY,"oui") -> 0 | AY8: =COUNTIFS(donnée!AK:AK,">=-0,25",donnée!AK:AK,"<=+0,25",donnée!CZ:CZ,"oui") -> 0
B9: -0,26 à -0,50 | C9: =COUNTIFS(donnée!AK:AK,">=-0,50",donnée!AK:AK,"<=-0,26",donnée!BO:BO,"oui") -> 0 | D9: =COUNTIFS(donnée!AK:AK,">=-0,50",donnée!AK:AK,"<=-0,26",donnée!BP:BP,"oui") -> 0 | E9: =COUNTIFS(donnée!AK:AK,">=-0,50",donnée!AK:AK,"<=-0,26",donnée!BQ:BQ,"oui") -> 0 | F9: =COUNTIFS(donnée!AK:AK,">=-0,50",donnée!AK:AK,"<=-0,26",donnée!BR:BR,"oui") -> 0 | G9: =COUNTIFS(donnée!AK:AK,">=-0,50",donnée!AK:AK,"<=-0,26",donnée!BS:BS,"oui") -> 0 | H9: =COUNTIFS(donnée!AK:AK,">=-0,50",donnée!AK:AK,"<=-0,26",donnée!BT:BT,"oui") -> 0 | I9: -0,26 à -0,50 | J9: =COUNTIFS(donnée!AK:AK,">=-0,50",donnée!AK:AK,"<=-0,26",donnée!BU:BU,"oui") -> 0 | K9: =COUNTIFS(donnée!AK:AK,">=-0,50",donnée!AK:AK,"<=-0,26",donnée!BV:BV,"oui") -> 0 | L9: =COUNTIFS(donnée!AK:AK,">=-0,50",donnée!AK:AK,"<=-0,26",donnée!BW:BW,"oui") -> 0 | M9: =COUNTIFS(donnée!AK:AK,">=-0,50",donnée!AK:AK,"<=-0,26",donnée!BX:BX,"oui") -> 0 | N9: =COUNTIFS(donnée!AK:AK,">=-0,50",donnée!AK:AK,"<=-0,26",donnée!BY:BY,"oui") -> 0 | O9: =COUNTIFS(donnée!AK:AK,">=-0,50",donnée!AK:AK,"<=-0,26",donnée!BZ:BZ,"oui") -> 0 | P9: -0,26 à -0,50 | Q9: =COUNTIFS(donnée!AK:AK,">=-0,50",donnée!AK:AK,"<=-0,26",donnée!CA:CA,"oui") -> 0 | R9: =COUNTIFS(donnée!AK:AK,">=-0,50",donnée!AK:AK,"<=-0,26",donnée!CB:CB,"oui") -> 0 | S9: =COUNTIFS(donnée!AK:AK,">=-0,50",donnée!AK:AK,"<=-0,26",donnée!CC:CC,"oui") -> 0 | T9: =COUNTIFS(donnée!AK:AK,">=-0,50",donnée!AK:AK,"<=-0,26",donnée!CD:CD,"oui") -> 0 | U9: =COUNTIFS(donnée!AK:AK,">=-0,50",donnée!AK:AK,"<=-0,26",donnée!CE:CE,"oui") -> 0 | V9: =COUNTIFS(donnée!AK:AK,">=-0,50",donnée!AK:AK,"<=-0,26",donnée!CF:CF,"oui") -> 0 | W9: -0,26 à -0,50 | X9: =COUNTIFS(donnée!AK:AK,">=-0,50",donnée!AK:AK,"<=-0,26",donnée!CG:CG,"oui") -> 0 | Y9: =COUNTIFS(donnée!AK:AK,">=-0,50",donnée!AK:AK,"<=-0,26",donnée!CH:CH,"oui") -> 0 | Z9: =COUNTIFS(donnée!AK:AK,">=-0,50",donnée!AK:AK,"<=-0,26",donnée!CI:CI,"oui") -> 0 | AA9: =COUNTIFS(donnée!AK:AK,">=-0,50",donnée!AK:AK,"<=-0,26",donnée!CJ:CJ,"oui") -> 0 | AB9: =COUNTIFS(donnée!AK:AK,">=-0,50",donnée!AK:AK,"<=-0,26",donnée!CK:CK,"oui") -> 0 | AD9: -0,26 à -0,50 | AE9: =COUNTIFS(donnée!AK:AK,">=-0,50",donnée!AK:AK,"<=-0,26",donnée!CL:CL,"oui") -> 0 | AF9: =COUNTIFS(donnée!AK:AK,">=-0,50",donnée!AK:AK,"<=-0,26",donnée!CM:CM,"oui") -> 0 | AG9: =COUNTIFS(donnée!AK:AK,">=-0,50",donnée!AK:AK,"<=-0,26",donnée!CN:CN,"oui") -> 0 | AH9: =COUNTIFS(donnée!AK:AK,">=-0,50",donnée!AK:AK,"<=-0,26",donnée!CO:CO,"oui") -> 0 | AK9: -0,26 à -0,50 | AL9: =COUNTIFS(donnée!AK:AK,">=-0,50",donnée!AK:AK,"<=-0,26",donnée!CP:CP,"oui") -> 0 | AM9: =COUNTIFS(donnée!AK:AK,">=-0,50",donnée!AK:AK,"<=-0,26",donnée!CQ:CQ,"oui") -> 0 | AN9: =COUNTIFS(donnée!AK:AK,">=-0,50",donnée!AK:AK,"<=-0,26",donnée!CR:CR,"oui") -> 0 | AO9: =COUNTIFS(donnée!AK:AK,">=-0,50",donnée!AK:AK,"<=-0,26",donnée!CS:CS,"oui") -> 0 | AR9: -0,26 à -0,50 | AS9: =COUNTIFS(donnée!AK:AK,">=-0,50",donnée!AK:AK,"<=-0,26",donnée!CT:CT,"oui") -> 0 | AT9: =COUNTIFS(donnée!AK:AK,">=-0,50",donnée!AK:AK,"<=-0,26",donnée!CU:CU,"oui") -> 0 | AU9: =COUNTIFS(donnée!AK:AK,">=-0,50",donnée!AK:AK,"<=-0,26",donnée!CV:CV,"oui") -> 0 | AV9: =COUNTIFS(donnée!AK:AK,">=-0,50",donnée!AK:AK,"<=-0,26",donnée!CW:CW,"oui") -> 0 | AW9: =COUNTIFS(donnée!AK:AK,">=-0,50",donnée!AK:AK,"<=-0,26",donnée!CX:CX,"oui") -> 0 | AX9: =COUNTIFS(donnée!AK:AK,">=-0,50",donnée!AK:AK,"<=-0,26",donnée!CY:CY,"oui") -> 0 | AY9: =COUNTIFS(donnée!AK:AK,">=-0,50",donnée!AK:AK,"<=-0,26",donnée!CZ:CZ,"oui") -> 0
B10: -0,51 à -0,75 | C10: =COUNTIFS(donnée!AK:AK,">=-0,75",donnée!AK:AK,"<=-0,51",donnée!BO:BO,"oui") -> 0 | D10: =COUNTIFS(donnée!AK:AK,">=-0,75",donnée!AK:AK,"<=-0,51",donnée!BP:BP,"oui") -> 0 | E10: =COUNTIFS(donnée!AK:AK,">=-0,75",donnée!AK:AK,"<=-0,51",donnée!BQ:BQ,"oui") -> 0 | F10: =COUNTIFS(donnée!AK:AK,">=-0,75",donnée!AK:AK,"<=-0,51",donnée!BR:BR,"oui") -> 0 | G10: =COUNTIFS(donnée!AK:AK,">=-0,75",donnée!AK:AK,"<=-0,51",donnée!BS:BS,"oui") -> 0 | H10: =COUNTIFS(donnée!AK:AK,">=-0,75",donnée!AK:AK,"<=-0,51",donnée!BT:BT,"oui") -> 0 | I10: -0,51 à -0,75 | J10: =COUNTIFS(donnée!AK:AK,">=-0,75",donnée!AK:AK,"<=-0,51",donnée!BU:BU,"oui") -> 0 | K10: =COUNTIFS(donnée!AK:AK,">=-0,75",donnée!AK:AK,"<=-0,51",donnée!BV:BV,"oui") -> 0 | L10: =COUNTIFS(donnée!AK:AK,">=-0,75",donnée!AK:AK,"<=-0,51",donnée!BW:BW,"oui") -> 0 | M10: =COUNTIFS(donnée!AK:AK,">=-0,75",donnée!AK:AK,"<=-0,51",donnée!BX:BX,"oui") -> 0 | N10: =COUNTIFS(donnée!AK:AK,">=-0,75",donnée!AK:AK,"<=-0,51",donnée!BY:BY,"oui") -> 0 | O10: =COUNTIFS(donnée!AP:AP,">=-0,75",donnée!AP:AP,"<=-0,51",donnée!BZ:BZ,"oui") -> 0 | P10: -0,51 à -0,75 | Q10: =COUNTIFS(donnée!AK:AK,">=-0,75",donnée!AK:AK,"<=-0,51",donnée!CA:CA,"oui") -> 0 | R10: =COUNTIFS(donnée!AK:AK,">=-0,75",donnée!AK:AK,"<=-0,51",donnée!CB:CB,"oui") -> 0 | S10: =COUNTIFS(donnée!AK:AK,">=-0,75",donnée!AK:AK,"<=-0,51",donnée!CC:CC,"oui") -> 0 | T10: =COUNTIFS(donnée!AK:AK,">=-0,75",donnée!AK:AK,"<=-0,51",donnée!CD:CD,"oui") -> 0 | U10: =COUNTIFS(donnée!AK:AK,">=-0,75",donnée!AK:AK,"<=-0,51",donnée!CE:CE,"oui") -> 0 | V10: =COUNTIFS(donnée!AK:AK,">=-0,75",donnée!AK:AK,"<=-0,51",donnée!CF:CF,"oui") -> 0 | W10: -0,51 à -0,75 | X10: =COUNTIFS(donnée!AK:AK,">=-0,75",donnée!AK:AK,"<=-0,51",donnée!CG:CG,"oui") -> 0 | Y10: =COUNTIFS(donnée!AK:AK,">=-0,75",donnée!AK:AK,"<=-0,51",donnée!CH:CH,"oui") -> 0 | Z10: =COUNTIFS(donnée!AK:AK,">=-0,75",donnée!AK:AK,"<=-0,51",donnée!CI:CI,"oui") -> 0 | AA10: =COUNTIFS(donnée!AK:AK,">=-0,75",donnée!AK:AK,"<=-0,51",donnée!CJ:CJ,"oui") -> 0 | AB10: =COUNTIFS(donnée!AK:AK,">=-0,75",donnée!AK:AK,"<=-0,51",donnée!CK:CK,"oui") -> 0 | AD10: -0,51 à -0,75 | AE10: =COUNTIFS(donnée!AK:AK,">=-0,75",donnée!AK:AK,"<=-0,51",donnée!CL:CL,"oui") -> 0 | AF10: =COUNTIFS(donnée!AK:AK,">=-0,75",donnée!AK:AK,"<=-0,51",donnée!CM:CM,"oui") -> 0 | AG10: =COUNTIFS(donnée!AK:AK,">=-0,75",donnée!AK:AK,"<=-0,51",donnée!CN:CN,"oui") -> 0 | AH10: =COUNTIFS(donnée!AK:AK,">=-0,75",donnée!AK:AK,"<=-0,51",donnée!CO:CO,"oui") -> 0 | AK10: -0,51 à -0,75 | AL10: =COUNTIFS(donnée!AK:AK,">=-0,75",donnée!AK:AK,"<=-0,51",donnée!CP:CP,"oui") -> 0 | AM10: =COUNTIFS(donnée!AK:AK,">=-0,75",donnée!AK:AK,"<=-0,51",donnée!CQ:CQ,"oui") -> 0 | AN10: =COUNTIFS(donnée!AK:AK,">=-0,75",donnée!AK:AK,"<=-0,51",donnée!CR:CR,"oui") -> 0 | AO10: =COUNTIFS(donnée!AK:AK,">=-0,75",donnée!AK:AK,"<=-0,51",donnée!CS:CS,"oui") -> 0 | AR10: -0,51 à -0,75 | AS10: =COUNTIFS(donnée!AK:AK,">=-0,75",donnée!AK:AK,"<=-0,51",donnée!CT:CT,"oui") -> 0 | AT10: =COUNTIFS(donnée!AK:AK,">=-0,75",donnée!AK:AK,"<=-0,51",donnée!CU:CU,"oui") -> 0 | AU10: =COUNTIFS(donnée!AK:AK,">=-0,75",donnée!AK:AK,"<=-0,51",donnée!CV:CV,"oui") -> 0 | AV10: =COUNTIFS(donnée!AK:AK,">=-0,75",donnée!AK:AK,"<=-0,51",donnée!CW:CW,"oui") -> 0 | AW10: =COUNTIFS(donnée!AK:AK,">=-0,75",donnée!AK:AK,"<=-0,51",donnée!CX:CX,"oui") -> 0 | AX10: =COUNTIFS(donnée!AK:AK,">=-0,75",donnée!AK:AK,"<=-0,51",donnée!CY:CY,"oui") -> 0 | AY10: =COUNTIFS(donnée!AK:AK,">=-0,75",donnée!AK:AK,"<=-0,51",donnée!CZ:CZ,"oui") -> 0
B11: -0,76 -1,0 | C11: =COUNTIFS(donnée!AK:AK,">=-1,0",donnée!AK:AK,"<=-0,76",donnée!BO:BO,"oui") -> 0 | D11: =COUNTIFS(donnée!AK:AK,">=-1,0",donnée!AK:AK,"<=-0,76",donnée!BP:BP,"oui") -> 0 | E11: =COUNTIFS(donnée!AK:AK,">=-1,0",donnée!AK:AK,"<=-0,76",donnée!BQ:BQ,"oui") -> 0 | F11: =COUNTIFS(donnée!AK:AK,">=-1,0",donnée!AK:AK,"<=-0,76",donnée!BR:BR,"oui") -> 0 | G11: =COUNTIFS(donnée!AK:AK,">=-1,0",donnée!AK:AK,"<=-0,76",donnée!BS:BS,"oui") -> 0 | H11: =COUNTIFS(donnée!AK:AK,">=-1,0",donnée!AK:AK,"<=-0,76",donnée!BT:BT,"oui") -> 0 | I11: -0,76 -1,0 | J11: =COUNTIFS(donnée!AK:AK,">=-1,0",donnée!AK:AK,"<=-0,76",donnée!BU:BU,"oui") -> 0 | K11: =COUNTIFS(donnée!AK:AK,">=-1,0",donnée!AK:AK,"<=-0,76",donnée!BV:BV,"oui") -> 0 | L11: =COUNTIFS(donnée!AK:AK,">=-1,0",donnée!AK:AK,"<=-0,76",donnée!BW:BW,"oui") -> 0 | M11: =COUNTIFS(donnée!AK:AK,">=-1,0",donnée!AK:AK,"<=-0,76",donnée!BX:BX,"oui") -> 0 | N11: =COUNTIFS(donnée!AK:AK,">=-1,0",donnée!AK:AK,"<=-0,76",donnée!BY:BY,"oui") -> 0 | O11: =COUNTIFS(donnée!AK:AK,">=-1,0",donnée!AK:AK,"<=-0,76",donnée!BZ:BZ,"oui") -> 0 | P11: -0,76 -1,0 | Q11: =COUNTIFS(donnée!AK:AK,">=-1,0",donnée!AK:AK,"<=-0,76",donnée!CA:CA,"oui") -> 0 | R11: =COUNTIFS(donnée!AK:AK,">=-1,0",donnée!AK:AK,"<=-0,76",donnée!CB:CB,"oui") -> 0 | S11: =COUNTIFS(donnée!AK:AK,">=-1,0",donnée!AK:AK,"<=-0,76",donnée!CC:CC,"oui") -> 0 | T11: =COUNTIFS(donnée!AK:AK,">=-1,0",donnée!AK:AK,"<=-0,76",donnée!CD:CD,"oui") -> 0 | U11: =COUNTIFS(donnée!AK:AK,">=-1,0",donnée!AK:AK,"<=-0,76",donnée!CE:CE,"oui") -> 0 | V11: =COUNTIFS(donnée!AK:AK,">=-1,0",donnée!AK:AK,"<=-0,76",donnée!CF:CF,"oui") -> 0 | W11: -0,76 -1,0 | X11: =COUNTIFS(donnée!AK:AK,">=-1,0",donnée!AK:AK,"<=-0,76",donnée!CG:CG,"oui") -> 0 | Y11: =COUNTIFS(donnée!AK:AK,">=-1,0",donnée!AK:AK,"<=-0,76",donnée!CH:CH,"oui") -> 0 | Z11: =COUNTIFS(donnée!AK:AK,">=-1,0",donnée!AK:AK,"<=-0,76",donnée!CI:CI,"oui") -> 0 | AA11: =COUNTIFS(donnée!AK:AK,">=-1,0",donnée!AK:AK,"<=-0,76",donnée!CJ:CJ,"oui") -> 0 | AB11: =COUNTIFS(donnée!AK:AK,">=-1,0",donnée!AK:AK,"<=-0,76",donnée!CK:CK,"oui") -> 0 | AD11: -0,76 -1,0 | AE11: =COUNTIFS(donnée!AK:AK,">=-1,0",donnée!AK:AK,"<=-0,76",donnée!CL:CL,"oui") -> 0 | AF11: =COUNTIFS(donnée!AK:AK,">=-1,0",donnée!AK:AK,"<=-0,76",donnée!CM:CM,"oui") -> 0 | AG11: =COUNTIFS(donnée!AK:AK,">=-1,0",donnée!AK:AK,"<=-0,76",donnée!CN:CN,"oui") -> 0 | AH11: =COUNTIFS(donnée!AK:AK,">=-1,0",donnée!AK:AK,"<=-0,76",donnée!CO:CO,"oui") -> 0 | AK11: -0,76 -1,0 | AL11: =COUNTIFS(donnée!AK:AK,">=-1,0",donnée!AK:AK,"<=-0,76",donnée!CP:CP,"oui") -> 0 | AM11: =COUNTIFS(donnée!AK:AK,">=-1,0",donnée!AK:AK,"<=-0,76",donnée!CQ:CQ,"oui") -> 0 | AN11: =COUNTIFS(donnée!AK:AK,">=-1,0",donnée!AK:AK,"<=-0,76",donnée!CR:CR,"oui") -> 0 | AO11: =COUNTIFS(donnée!AK:AK,">=-1,0",donnée!AK:AK,"<=-0,76",donnée!CS:CS,"oui") -> 0 | AR11: -0,76 -1,0 | AS11: =COUNTIFS(donnée!AK:AK,">=-1,0",donnée!AK:AK,"<=-0,76",donnée!CT:CT,"oui") -> 0 | AT11: =COUNTIFS(donnée!AK:AK,">=-1,0",donnée!AK:AK,"<=-0,76",donnée!CU:CU,"oui") -> 0 | AU11: =COUNTIFS(donnée!AK:AK,">=-1,0",donnée!AK:AK,"<=-0,76",donnée!CV:CV,"oui") -> 0 | AV11: =COUNTIFS(donnée!AK:AK,">=-1,0",donnée!AK:AK,"<=-0,76",donnée!CW:CW,"oui") -> 0 | AW11: =COUNTIFS(donnée!AK:AK,">=-1,0",donnée!AK:AK,"<=-0,76",donnée!CX:CX,"oui") -> 0 | AX11: =COUNTIFS(donnée!AK:AK,">=-1,0",donnée!AK:AK,"<=-0,76",donnée!CY:CY,"oui") -> 0 | AY11: =COUNTIFS(donnée!AK:AK,">=-1,0",donnée!AK:AK,"<=-0,76",donnée!CZ:CZ,"oui") -> 0
B12: > -1,0 | C12: =COUNTIFS(donnée!AK:AK,"<=-1,0",donnée!BO:BO,"oui") -> 0 | D12: =COUNTIFS(donnée!AK:AK,"<=-1,0",donnée!BP:BP,"oui") -> 0 | E12: =COUNTIFS(donnée!AK:AK,"<=-1,0",donnée!BQ:BQ,"oui") -> 0 | F12: =COUNTIFS(donnée!AK:AK,"<=-1,0",donnée!BR:BR,"oui") -> 0 | G12: =COUNTIFS(donnée!AK:AK,"<=-1,0",donnée!BS:BS,"oui") -> 0 | H12: =COUNTIFS(donnée!AK:AK,"<=-1,0",donnée!BT:BT,"oui") -> 0 | I12: > -1,0 | J12: =COUNTIFS(donnée!AK:AK,"<=-1,0",donnée!BU:BU,"oui") -> 0 | K12: =COUNTIFS(donnée!AK:AK,"<=-1,0",donnée!BV:BV,"oui") -> 0 | L12: =COUNTIFS(donnée!AK:AK,"<=-1,0",donnée!BW:BW,"oui") -> 0 | M12: =COUNTIFS(donnée!AK:AK,"<=-1,0",donnée!BX:BX,"oui") -> 0 | N12: =COUNTIFS(donnée!AK:AK,"<=-1,0",donnée!BY:BY,"oui") -> 0 | O12: =COUNTIFS(donnée!AK:AK,"<=-1,0",donnée!BZ:BZ,"oui") -> 0 | P12: > -1,0 | Q12: =COUNTIFS(donnée!AK:AK,"<=-1,0",donnée!CA:CA,"oui") -> 0 | R12: =COUNTIFS(donnée!AK:AK,"<=-1,0",donnée!CB:CB,"oui") -> 0 | S12: =COUNTIFS(donnée!AK:AK,"<=-1,0",donnée!CC:CC,"oui") -> 0 | T12: =COUNTIFS(donnée!AK:AK,"<=-1,0",donnée!CD:CD,"oui") -> 0 | U12: =COUNTIFS(donnée!AK:AK,"<=-1,0",donnée!CE:CE,"oui") -> 0 | V12: =COUNTIFS(donnée!AK:AK,"<=-1,0",donnée!CF:CF,"oui") -> 0 | W12: > -1,0 | X12: =COUNTIFS(donnée!AK:AK,"<=-1,0",donnée!CG:CG,"oui") -> 0 | Y12: =COUNTIFS(donnée!AK:AK,"<=-1,0",donnée!CH:CH,"oui") -> 0 | Z12: =COUNTIFS(donnée!AK:AK,"<=-1,0",donnée!CI:CI,"oui") -> 0 | AA12: =COUNTIFS(donnée!AK:AK,"<=-1,0",donnée!CJ:CJ,"oui") -> 0 | AB12: =COUNTIFS(donnée!AK:AK,"<=-1,0",donnée!CK:CK,"oui") -> 0 | AD12: > -1,0 | AE12: =COUNTIFS(donnée!AK:AK,"<=-1,0",donnée!CL:CL,"oui") -> 0 | AF12: =COUNTIFS(donnée!AK:AK,"<=-1,0",donnée!CM:CM,"oui") -> 0 | AG12: =COUNTIFS(donnée!AK:AK,"<=-1,0",donnée!CN:CN,"oui") -> 0 | AH12: =COUNTIFS(donnée!AK:AK,"<=-1,0",donnée!CO:CO,"oui") -> 0 | AK12: > -1,0 | AL12: =COUNTIFS(donnée!AK:AK,"<=-1,0",donnée!CP:CP,"oui") -> 0 | AM12: =COUNTIFS(donnée!AK:AK,"<=-1,0",donnée!CQ:CQ,"oui") -> 0 | AN12: =COUNTIFS(donnée!AK:AK,"<=-1,0",donnée!CR:CR,"oui") -> 0 | AO12: =COUNTIFS(donnée!AK:AK,"<=-1,0",donnée!CS:CS,"oui") -> 0 | AR12: > -1,0 | AS12: =COUNTIFS(donnée!AK:AK,"<=-1,0",donnée!CT:CT,"oui") -> 0 | AT12: =COUNTIFS(donnée!AK:AK,"<=-1,0",donnée!CU:CU,"oui") -> 0 | AU12: =COUNTIFS(donnée!AK:AK,"<=-1,0",donnée!CV:CV,"oui") -> 0 | AV12: =COUNTIFS(donnée!AK:AK,"<=-1,0",donnée!CW:CW,"oui") -> 0 | AW12: =COUNTIFS(donnée!AK:AK,"<=-1,0",donnée!CX:CX,"oui") -> 0 | AX12: =COUNTIFS(donnée!AK:AK,"<=-1,0",donnée!CY:CY,"oui") -> 0 | AY12: =COUNTIFS(donnée!AK:AK,"<=-1,0",donnée!CZ:CZ,"oui") -> 0
C30: PUISSANCE IOL =>30 | D30: PUISSANCE IOL 30 => 25 | E30: PUISSANCE IOL 25 => 15 | F30: PUISSANCE IOL 15 => 10 | G30: PUISSANCE IOL 10 => 0 | H30: PUISSANCE IOL 0=> | J30: œil extrème >28mm | K30: Œil très long 28>26 | L30: Œil long 26>24,5 | M30: Œil long NORMAL 24,5>22,5 | N30: Œil court 22,5>20 | O30: Œil très court <20 | Q30: K extrème >48,5 | R30: K CAMBRE 48,5>46,5 | S30: K CAMBRE- 46,5>45 | T30: K NORM 45>43 | U30: K PLAT- 43>41 | V30: K PLAT >41,0 | X30: CA extrème >4,0 | Y30: CA profonde 4>3,5 | Z30: CA NORM 3,5>2,5 | AA30: CA ETROITE 2,5>2,0 | AB30: CA tres etroite <2,0 | AE30: LT TRES EPAIS >5,3 | AF30: LT EPAIS 5,3>4,9 | AG30: LT NORMAL 4,9>3,8 | AH30: LT FIN>3,8 | AL30: WTW EXTREME >13 | AM30: WTW GRAND 13>12,5 | AN30: WTW NORM 12,5>11,5 | AO30: WTW PETITE <11,5 | AS30: AGE +90 | AT30: AGE 89 => 80 | AU30: AGE 80 => 70 | AV30: AGE 69 => 60 | AW30: AGE 59 => 50 | AX30: AGE 49 => 40 | AY30: AGE -39
B31: HAIGIS | I31: HAIGIS | P31: HAIGIS | W31: HAIGIS | AD31: HAIGIS | AK31: HAIGIS | AR31: HAIGIS
A32: =COUNTIFS(donnée!AN:AN,">=1,0") -> 0 | B32: >+1,0 | C32: =COUNTIFS(donnée!AN:AN,">=1,0",donnée!BO:BO,"oui") -> 0 | D32: =COUNTIFS(donnée!AN:AN,">=1,0",donnée!BP:BP,"oui") -> 0 | E32: =COUNTIFS(donnée!AN:AN,">=1,0",donnée!BQ:BQ,"oui") -> 0 | F32: =COUNTIFS(donnée!AN:AN,">=1,0",donnée!BR:BR,"oui") -> 0 | G32: =COUNTIFS(donnée!AN:AN,">=1,0",donnée!BS:BS,"oui") -> 0 | H32: =COUNTIFS(donnée!AN:AN,">=1,0",donnée!BT:BT,"oui") -> 0 | I32: >+1,0 | J32: =COUNTIFS(donnée!AN:AN,">=1,0",donnée!BU:BU,"oui") -> 0 | K32: =COUNTIFS(donnée!AN:AN,">=1,0",donnée!BV:BV,"oui") -> 0 | L32: =COUNTIFS(donnée!AN:AN,">=1,0",donnée!BW:BW,"oui") -> 0 | M32: =COUNTIFS(donnée!AN:AN,">=1,0",donnée!BX:BX,"oui") -> 0 | N32: =COUNTIFS(donnée!AN:AN,">=1,0",donnée!BY:BY,"oui") -> 0 | O32: =COUNTIFS(donnée!AN:AN,">=1,0",donnée!BZ:BZ,"oui") -> 0 | P32: >+1,0 | Q32: =COUNTIFS(donnée!AN:AN,">=1,0",donnée!CA:CA,"oui") -> 0 | R32: =COUNTIFS(donnée!AN:AN,">=1,0",donnée!CB:CB,"oui") -> 0 | S32: =COUNTIFS(donnée!AN:AN,">=1,0",donnée!CC:CC,"oui") -> 0 | T32: =COUNTIFS(donnée!AN:AN,">=1,0",donnée!CD:CD,"oui") -> 0 | U32: =COUNTIFS(donnée!AN:AN,">=1,0",donnée!CE:CE,"oui") -> 0 | V32: =COUNTIFS(donnée!AN:AN,">=1,0",donnée!CF:CF,"oui") -> 0 | W32: >+1,0 | X32: =COUNTIFS(donnée!AN:AN,">=1,0",donnée!CG:CG,"oui") -> 0 | Y32: =COUNTIFS(donnée!AN:AN,">=1,0",donnée!CH:CH,"oui") -> 0 | Z32: =COUNTIFS(donnée!AN:AN,">=1,0",donnée!CI:CI,"oui") -> 0 | AA32: =COUNTIFS(donnée!AN:AN,">=1,0",donnée!CJ:CJ,"oui") -> 0 | AB32: =COUNTIFS(donnée!AN:AN,">=1,0",donnée!CK:CK,"oui") -> 0 | AD32: >+1,0 | AE32: =COUNTIFS(donnée!AN:AN,">=1,0",donnée!CL:CL,"oui") -> 0 | AF32: =COUNTIFS(donnée!AN:AN,">=1,0",donnée!CM:CM,"oui") -> 0 | AG32: =COUNTIFS(donnée!AN:AN,">=1,0",donnée!CN:CN,"oui") -> 0 | AH32: =COUNTIFS(donnée!AN:AN,">=1,0",donnée!CO:CO,"oui") -> 0 | AK32: >+1,0 | AL32: =COUNTIFS(donnée!AN:AN,">=1,0",donnée!CP:CP,"oui") -> 0 | AM32: =COUNTIFS(donnée!AN:AN,">=1,0",donnée!CQ:CQ,"oui") -> 0 | AN32: =COUNTIFS(donnée!AN:AN,">=1,0",donnée!CR:CR,"oui") -> 0 | AO32: =COUNTIFS(donnée!AN:AN,">=1,0",donnée!CS:CS,"oui") -> 0 | AR32: >+1,0 | AS32: =COUNTIFS(donnée!$AN:$AN,">=1,0",donnée!CT:CT,"oui") -> 0 | AT32: =COUNTIFS(donnée!$AN:$AN,">=1,0",donnée!CU:CU,"oui") -> 0 | AU32: =COUNTIFS(donnée!$AN:$AN,">=1,0",donnée!CV:CV,"oui") -> 0 | AV32: =COUNTIFS(donnée!$AN:$AN,">=1,0",donnée!CW:CW,"oui") -> 0 | AW32: =COUNTIFS(donnée!$AN:$AN,">=1,0",donnée!CX:CX,"oui") -> 0 | AX32: =COUNTIFS(donnée!$AN:$AN,">=1,0",donnée!CY:CY,"oui") -> 0 | AY32: =COUNTIFS(donnée!$AN:$AN,">=1,0",donnée!CZ:CZ,"oui") -> 0
A33: =COUNTIFS(donnée!AN:AN,">=0,76",donnée!AN:AN,"<=1,0") -> 0 | B33: +1,0 à +0,76 | C33: =COUNTIFS(donnée!AN:AN,">=0,76",donnée!AN:AN,"<=1,0",donnée!BO:BO,"oui") -> 0 | D33: =COUNTIFS(donnée!AN:AN,">=0,76",donnée!AN:AN,"<=1,0",donnée!BP:BP,"oui") -> 0 | E33: =COUNTIFS(donnée!AN:AN,">=0,76",donnée!AN:AN,"<=1,0",donnée!BQ:BQ,"oui") -> 0 | F33: =COUNTIFS(donnée!AN:AN,">=0,76",donnée!AN:AN,"<=1,0",donnée!BR:BR,"oui") -> 0 | G33: =COUNTIFS(donnée!AN:AN,">=0,76",donnée!AN:AN,"<=1,0",donnée!BS:BS,"oui") -> 0 | H33: =COUNTIFS(donnée!AN:AN,">=0,76",donnée!AN:AN,"<=1,0",donnée!BT:BT,"oui") -> 0 | I33: +1,0 à +0,76 | J33: =COUNTIFS(donnée!AN:AN,">=0,76",donnée!AN:AN,"<=1,0",donnée!BU:BU,"oui") -> 0 | K33: =COUNTIFS(donnée!AN:AN,">=0,76",donnée!AN:AN,"<=1,0",donnée!BV:BV,"oui") -> 0 | L33: =COUNTIFS(donnée!AN:AN,">=0,76",donnée!AN:AN,"<=1,0",donnée!BW:BW,"oui") -> 0 | M33: =COUNTIFS(donnée!AN:AN,">=0,76",donnée!AN:AN,"<=1,0",donnée!BX:BX,"oui") -> 0 | N33: =COUNTIFS(donnée!AN:AN,">=0,76",donnée!AR:AR,"<=1,0",donnée!BY:BY,"oui") -> 0 | O33: =COUNTIFS(donnée!AN:AN,">=0,76",donnée!AN:AN,"<=1,0",donnée!BZ:BZ,"oui") -> 0 | P33: +1,0 à +0,76 | Q33: =COUNTIFS(donnée!AN:AN,">=0,76",donnée!AN:AN,"<=1,0",donnée!CA:CA,"oui") -> 0 | R33: =COUNTIFS(donnée!AN:AN,">=0,76",donnée!AN:AN,"<=1,0",donnée!CB:CB,"oui") -> 0 | S33: =COUNTIFS(donnée!AN:AN,">=0,76",donnée!AN:AN,"<=1,0",donnée!CC:CC,"oui") -> 0 | T33: =COUNTIFS(donnée!AN:AN,">=0,76",donnée!AN:AN,"<=1,0",donnée!CD:CD,"oui") -> 0 | U33: =COUNTIFS(donnée!AN:AN,">=0,76",donnée!AN:AN,"<=1,0",donnée!CE:CE,"oui") -> 0 | V33: =COUNTIFS(donnée!AN:AN,">=0,76",donnée!AN:AN,"<=1,0",donnée!CF:CF,"oui") -> 0 | W33: +1,0 à +0,76 | X33: =COUNTIFS(donnée!AN:AN,">=0,76",donnée!AN:AN,"<=1,0",donnée!CG:CG,"oui") -> 0 | Y33: =COUNTIFS(donnée!AN:AN,">=0,76",donnée!AN:AN,"<=1,0",donnée!CH:CH,"oui") -> 0 | Z33: =COUNTIFS(donnée!AN:AN,">=0,76",donnée!AN:AN,"<=1,0",donnée!CI:CI,"oui") -> 0 | AA33: =COUNTIFS(donnée!AN:AN,">=0,76",donnée!AN:AN,"<=1,0",donnée!CJ:CJ,"oui") -> 0 | AB33: =COUNTIFS(donnée!AN:AN,">=0,76",donnée!AN:AN,"<=1,0",donnée!CK:CK,"oui") -> 0 | AD33: +1,0 à +0,76 | AE33: =COUNTIFS(donnée!AN:AN,">=0,76",donnée!AN:AN,"<=1,0",donnée!CL:CL,"oui") -> 0 | AF33: =COUNTIFS(donnée!AN:AN,">=0,76",donnée!AN:AN,"<=1,0",donnée!CM:CM,"oui") -> 0 | AG33: =COUNTIFS(donnée!AN:AN,">=0,76",donnée!AN:AN,"<=1,0",donnée!CN:CN,"oui") -> 0 | AH33: =COUNTIFS(donnée!AN:AN,">=0,76",donnée!AN:AN,"<=1,0",donnée!CO:CO,"oui") -> 0 | AK33: +1,0 à +0,76 | AL33: =COUNTIFS(donnée!AN:AN,">=0,76",donnée!AN:AN,"<=1,0",donnée!CP:CP,"oui") -> 0 | AM33: =COUNTIFS(donnée!AN:AN,">=0,76",donnée!AN:AN,"<=1,0",donnée!CQ:CQ,"oui") -> 0 | AN33: =COUNTIFS(donnée!AN:AN,">=0,76",donnée!AN:AN,"<=1,0",donnée!CR:CR,"oui") -> 0 | AO33: =COUNTIFS(donnée!AN:AN,">=0,76",donnée!AN:AN,"<=1,0",donnée!CS:CS,"oui") -> 0 | AR33: +1,0 à +0,76 | AS33: =COUNTIFS(donnée!$AN:$AN,">=0,76",donnée!$AN:$AN,"<=1,0",donnée!CT:CT,"oui") -> 0 | AT33: =COUNTIFS(donnée!$AN:$AN,">=0,76",donnée!$AN:$AN,"<=1,0",donnée!CU:CU,"oui") -> 0 | AU33: =COUNTIFS(donnée!$AN:$AN,">=0,76",donnée!$AN:$AN,"<=1,0",donnée!CV:CV,"oui") -> 0 | AV33: =COUNTIFS(donnée!$AN:$AN,">=0,76",donnée!$AN:$AN,"<=1,0",donnée!CW:CW,"oui") -> 0 | AW33: =COUNTIFS(donnée!$AN:$AN,">=0,76",donnée!$AN:$AN,"<=1,0",donnée!CX:CX,"oui") -> 0 | AX33: =COUNTIFS(donnée!$AN:$AN,">=0,76",donnée!$AN:$AN,"<=1,0",donnée!CY:CY,"oui") -> 0 | AY33: =COUNTIFS(donnée!$AN:$AN,">=0,76",donnée!$AN:$AN,"<=1,0",donnée!CZ:CZ,"oui") -> 0
A34: =COUNTIFS(donnée!AN:AN,">=+0,51",donnée!AN:AN,"<=+0,75") -> 0 | B34: +0,75 à +0,51 | C34: =COUNTIFS(donnée!AN:AN,">=+0,51",donnée!AN:AN,"<=+0,75",donnée!BO:BO,"oui") -> 0 | D34: =COUNTIFS(donnée!AN:AN,">=+0,51",donnée!AN:AN,"<=+0,75",donnée!BP:BP,"oui") -> 0 | E34: =COUNTIFS(donnée!AN:AN,">=+0,51",donnée!AN:AN,"<=+0,75",donnée!BQ:BQ,"oui") -> 0 | F34: =COUNTIFS(donnée!AN:AN,">=+0,51",donnée!AN:AN,"<=+0,75",donnée!BR:BR,"oui") -> 0 | G34: =COUNTIFS(donnée!AN:AN,">=+0,51",donnée!AN:AN,"<=+0,75",donnée!BS:BS,"oui") -> 0 | H34: =COUNTIFS(donnée!AN:AN,">=+0,51",donnée!AN:AN,"<=+0,75",donnée!BT:BT,"oui") -> 0 | I34: +0,75 à +0,51 | J34: =COUNTIFS(donnée!AN:AN,">=+0,51",donnée!AN:AN,"<=+0,75",donnée!BU:BU,"oui") -> 0 | K34: =COUNTIFS(donnée!AN:AN,">=+0,51",donnée!AN:AN,"<=+0,75",donnée!BV:BV,"oui") -> 0 | L34: =COUNTIFS(donnée!AN:AN,">=+0,51",donnée!AN:AN,"<=+0,75",donnée!BW:BW,"oui") -> 0 | M34: =COUNTIFS(donnée!AN:AN,">=+0,51",donnée!AN:AN,"<=+0,75",donnée!BX:BX,"oui") -> 0 | N34: =COUNTIFS(donnée!AN:AN,">=+0,51",donnée!AN:AN,"<=+0,75",donnée!BY:BY,"oui") -> 0 | O34: =COUNTIFS(donnée!AN:AN,">=+0,51",donnée!AN:AN,"<=+0,75",donnée!BZ:BZ,"oui") -> 0 | P34: +0,75 à +0,51 | Q34: =COUNTIFS(donnée!AN:AN,">=+0,51",donnée!AN:AN,"<=+0,75",donnée!CA:CA,"oui") -> 0 | R34: =COUNTIFS(donnée!AN:AN,">=+0,51",donnée!AN:AN,"<=+0,75",donnée!CB:CB,"oui") -> 0 | S34: =COUNTIFS(donnée!AN:AN,">=+0,51",donnée!AN:AN,"<=+0,75",donnée!CC:CC,"oui") -> 0 | T34: =COUNTIFS(donnée!AN:AN,">=+0,51",donnée!AN:AN,"<=+0,75",donnée!CD:CD,"oui") -> 0 | U34: =COUNTIFS(donnée!AN:AN,">=+0,51",donnée!AN:AN,"<=+0,75",donnée!CE:CE,"oui") -> 0 | V34: =COUNTIFS(donnée!AN:AN,">=+0,51",donnée!AN:AN,"<=+0,75",donnée!CF:CF,"oui") -> 0 | W34: +0,75 à +0,51 | X34: =COUNTIFS(donnée!AN:AN,">=+0,51",donnée!AN:AN,"<=+0,75",donnée!CG:CG,"oui") -> 0 | Y34: =COUNTIFS(donnée!AN:AN,">=+0,51",donnée!AN:AN,"<=+0,75",donnée!CH:CH,"oui") -> 0 | Z34: =COUNTIFS(donnée!AN:AN,">=+0,51",donnée!AN:AN,"<=+0,75",donnée!CI:CI,"oui") -> 0 | AA34: =COUNTIFS(donnée!AN:AN,">=+0,51",donnée!AN:AN,"<=+0,75",donnée!CJ:CJ,"oui") -> 0 | AB34: =COUNTIFS(donnée!AN:AN,">=+0,51",donnée!AN:AN,"<=+0,75",donnée!CK:CK,"oui") -> 0 | AD34: +0,75 à +0,51 | AE34: =COUNTIFS(donnée!AN:AN,">=+0,51",donnée!AN:AN,"<=+0,75",donnée!CL:CL,"oui") -> 0 | AF34: =COUNTIFS(donnée!AN:AN,">=+0,51",donnée!AN:AN,"<=+0,75",donnée!CM:CM,"oui") -> 0 | AG34: =COUNTIFS(donnée!AN:AN,">=+0,51",donnée!AN:AN,"<=+0,75",donnée!CN:CN,"oui") -> 0 | AH34: =COUNTIFS(donnée!AN:AN,">=+0,51",donnée!AN:AN,"<=+0,75",donnée!CO:CO,"oui") -> 0 | AK34: +0,75 à +0,51 | AL34: =COUNTIFS(donnée!AN:AN,">=+0,51",donnée!AN:AN,"<=+0,75",donnée!CP:CP,"oui") -> 0 | AM34: =COUNTIFS(donnée!AN:AN,">=+0,51",donnée!AN:AN,"<=+0,75",donnée!CQ:CQ,"oui") -> 0 | AN34: =COUNTIFS(donnée!AN:AN,">=+0,51",donnée!AN:AN,"<=+0,75",donnée!CR:CR,"oui") -> 0 | AO34: =COUNTIFS(donnée!AN:AN,">=+0,51",donnée!AN:AN,"<=+0,75",donnée!CS:CS,"oui") -> 0 | AR34: +0,75 à +0,51 | AS34: =COUNTIFS(donnée!$AN:$AN,">=+0,51",donnée!$AN:$AN,"<=+0,75",donnée!CT:CT,"oui") -> 0 | AT34: =COUNTIFS(donnée!$AN:$AN,">=+0,51",donnée!$AN:$AN,"<=+0,75",donnée!CU:CU,"oui") -> 0 | AU34: =COUNTIFS(donnée!$AN:$AN,">=+0,51",donnée!$AN:$AN,"<=+0,75",donnée!CV:CV,"oui") -> 0 | AV34: =COUNTIFS(donnée!$AN:$AN,">=+0,51",donnée!$AN:$AN,"<=+0,75",donnée!CW:CW,"oui") -> 0 | AW34: =COUNTIFS(donnée!$AN:$AN,">=+0,51",donnée!$AN:$AN,"<=+0,75",donnée!CX:CX,"oui") -> 0 | AX34: =COUNTIFS(donnée!$AN:$AN,">=+0,51",donnée!$AN:$AN,"<=+0,75",donnée!CY:CY,"oui") -> 0 | AY34: =COUNTIFS(donnée!$AN:$AN,">=+0,51",donnée!$AN:$AN,"<=+0,75",donnée!CZ:CZ,"oui") -> 0
A35: =COUNTIFS(donnée!AN:AN,">=+0,26",donnée!AN:AN,"<=+0,50") -> 0 | B35: +0,50 à +0,26 | C35: =COUNTIFS(donnée!AN:AN,">=+0,26",donnée!AN:AN,"<=+0,50",donnée!BO:BO,"oui") -> 0 | D35: =COUNTIFS(donnée!AN:AN,">=+0,26",donnée!AN:AN,"<=+0,50",donnée!BP:BP,"oui") -> 0 | E35: =COUNTIFS(donnée!AN:AN,">=+0,26",donnée!AN:AN,"<=+0,50",donnée!BQ:BQ,"oui") -> 0 | F35: =COUNTIFS(donnée!AN:AN,">=+0,26",donnée!AN:AN,"<=+0,50",donnée!BR:BR,"oui") -> 0 | G35: =COUNTIFS(donnée!AN:AN,">=+0,26",donnée!AN:AN,"<=+0,50",donnée!BS:BS,"oui") -> 0 | H35: =COUNTIFS(donnée!AN:AN,">=+0,26",donnée!AN:AN,"<=+0,50",donnée!BT:BT,"oui") -> 0 | I35: +0,50 à +0,26 | J35: =COUNTIFS(donnée!AN:AN,">=+0,26",donnée!AN:AN,"<=+0,50",donnée!BU:BU,"oui") -> 0 | K35: =COUNTIFS(donnée!AN:AN,">=+0,26",donnée!AN:AN,"<=+0,50",donnée!BV:BV,"oui") -> 0 | L35: =COUNTIFS(donnée!AN:AN,">=+0,26",donnée!AN:AN,"<=+0,50",donnée!BW:BW,"oui") -> 0 | M35: =COUNTIFS(donnée!AN:AN,">=+0,26",donnée!AN:AN,"<=+0,50",donnée!BX:BX,"oui") -> 0 | N35: =COUNTIFS(donnée!AN:AN,">=+0,26",donnée!AN:AN,"<=+0,50",donnée!BY:BY,"oui") -> 0 | O35: =COUNTIFS(donnée!AN:AN,">=+0,26",donnée!AN:AN,"<=+0,50",donnée!BZ:BZ,"oui") -> 0 | P35: +0,50 à +0,26 | Q35: =COUNTIFS(donnée!AN:AN,">=+0,26",donnée!AN:AN,"<=+0,50",donnée!CA:CA,"oui") -> 0 | R35: =COUNTIFS(donnée!AN:AN,">=+0,26",donnée!AN:AN,"<=+0,50",donnée!CB:CB,"oui") -> 0 | S35: =COUNTIFS(donnée!AN:AN,">=+0,26",donnée!AN:AN,"<=+0,50",donnée!CC:CC,"oui") -> 0 | T35: =COUNTIFS(donnée!AN:AN,">=+0,26",donnée!AN:AN,"<=+0,50",donnée!CD:CD,"oui") -> 0 | U35: =COUNTIFS(donnée!AN:AN,">=+0,26",donnée!AN:AN,"<=+0,50",donnée!CE:CE,"oui") -> 0 | V35: =COUNTIFS(donnée!AN:AN,">=+0,26",donnée!AN:AN,"<=+0,50",donnée!CF:CF,"oui") -> 0 | W35: +0,50 à +0,26 | X35: =COUNTIFS(donnée!AN:AN,">=+0,26",donnée!AN:AN,"<=+0,50",donnée!CG:CG,"oui") -> 0 | Y35: =COUNTIFS(donnée!AN:AN,">=+0,26",donnée!AN:AN,"<=+0,50",donnée!CH:CH,"oui") -> 0 | Z35: =COUNTIFS(donnée!AN:AN,">=+0,26",donnée!AN:AN,"<=+0,50",donnée!CI:CI,"oui") -> 0 | AA35: =COUNTIFS(donnée!AN:AN,">=+0,26",donnée!AN:AN,"<=+0,50",donnée!CJ:CJ,"oui") -> 0 | AB35: =COUNTIFS(donnée!AN:AN,">=+0,26",donnée!AN:AN,"<=+0,50",donnée!CK:CK,"oui") -> 0 | AD35: +0,50 à +0,26 | AE35: =COUNTIFS(donnée!AN:AN,">=+0,26",donnée!AN:AN,"<=+0,50",donnée!CL:CL,"oui") -> 0 | AF35: =COUNTIFS(donnée!AN:AN,">=+0,26",donnée!AN:AN,"<=+0,50",donnée!CM:CM,"oui") -> 0 | AG35: =COUNTIFS(donnée!AN:AN,">=+0,26",donnée!AN:AN,"<=+0,50",donnée!CN:CN,"oui") -> 0 | AH35: =COUNTIFS(donnée!AN:AN,">=+0,26",donnée!AN:AN,"<=+0,50",donnée!CO:CO,"oui") -> 0 | AK35: +0,50 à +0,26 | AL35: =COUNTIFS(donnée!AN:AN,">=+0,26",donnée!AN:AN,"<=+0,50",donnée!CP:CP,"oui") -> 0 | AM35: =COUNTIFS(donnée!AN:AN,">=+0,26",donnée!AN:AN,"<=+0,50",donnée!CQ:CQ,"oui") -> 0 | AN35: =COUNTIFS(donnée!AN:AN,">=+0,26",donnée!AN:AN,"<=+0,50",donnée!CR:CR,"oui") -> 0 | AO35: =COUNTIFS(donnée!AN:AN,">=+0,26",donnée!AN:AN,"<=+0,50",donnée!CS:CS,"oui") -> 0 | AR35: +0,50 à +0,26 | AS35: =COUNTIFS(donnée!$AN:$AN,">=+0,26",donnée!$AN:$AN,"<=+0,50",donnée!CT:CT,"oui") -> 0 | AT35: =COUNTIFS(donnée!$AN:$AN,">=+0,26",donnée!$AN:$AN,"<=+0,50",donnée!CU:CU,"oui") -> 0 | AU35: =COUNTIFS(donnée!$AN:$AN,">=+0,26",donnée!$AN:$AN,"<=+0,50",donnée!CV:CV,"oui") -> 0 | AV35: =COUNTIFS(donnée!$AN:$AN,">=+0,26",donnée!$AN:$AN,"<=+0,50",donnée!CW:CW,"oui") -> 0 | AW35: =COUNTIFS(donnée!$AN:$AN,">=+0,26",donnée!$AN:$AN,"<=+0,50",donnée!CX:CX,"oui") -> 0 | AX35: =COUNTIFS(donnée!$AN:$AN,">=+0,26",donnée!$AN:$AN,"<=+0,50",donnée!CY:CY,"oui") -> 0 | AY35: =COUNTIFS(donnée!$AN:$AN,">=+0,26",donnée!$AN:$AN,"<=+0,50",donnée!CZ:CZ,"oui") -> 0
A36: =COUNTIFS(donnée!AN:AN,">=-0,25",donnée!AN:AN,"<=+0,25") -> 0 | B36: +0,25 à -0,25 | C36: =COUNTIFS(donnée!AN:AN,">=-0,25",donnée!AN:AN,"<=+0,25",donnée!BO:BO,"oui") -> 0 | D36: =COUNTIFS(donnée!AN:AN,">=-0,25",donnée!AN:AN,"<=+0,25",donnée!BP:BP,"oui") -> 0 | E36: =COUNTIFS(donnée!AN:AN,">=-0,25",donnée!AN:AN,"<=+0,25",donnée!BQ:BQ,"oui") -> 0 | F36: =COUNTIFS(donnée!AN:AN,">=-0,25",donnée!AN:AN,"<=+0,25",donnée!BR:BR,"oui") -> 0 | G36: =COUNTIFS(donnée!AN:AN,">=-0,25",donnée!AN:AN,"<=+0,25",donnée!BS:BS,"oui") -> 0 | H36: =COUNTIFS(donnée!AN:AN,">=-0,25",donnée!AN:AN,"<=+0,25",donnée!BT:BT,"oui") -> 0 | I36: +0,25 à -0,25 | J36: =COUNTIFS(donnée!AN:AN,">=-0,25",donnée!AN:AN,"<=+0,25",donnée!BU:BU,"oui") -> 0 | K36: =COUNTIFS(donnée!AN:AN,">=-0,25",donnée!AN:AN,"<=+0,25",donnée!BV:BV,"oui") -> 0 | L36: =COUNTIFS(donnée!AN:AN,">=-0,25",donnée!AN:AN,"<=+0,25",donnée!BW:BW,"oui") -> 0 | M36: =COUNTIFS(donnée!AN:AN,">=-0,25",donnée!AN:AN,"<=+0,25",donnée!BX:BX,"oui") -> 0 | N36: =COUNTIFS(donnée!AN:AN,">=-0,25",donnée!AN:AN,"<=+0,25",donnée!BY:BY,"oui") -> 0 | O36: =COUNTIFS(donnée!AN:AN,">=-0,25",donnée!AN:AN,"<=+0,25",donnée!BZ:BZ,"oui") -> 0 | P36: +0,25 à -0,25 | Q36: =COUNTIFS(donnée!AN:AN,">=-0,25",donnée!AN:AN,"<=+0,25",donnée!CA:CA,"oui") -> 0 | R36: =COUNTIFS(donnée!AN:AN,">=-0,25",donnée!AN:AN,"<=+0,25",donnée!CB:CB,"oui") -> 0 | S36: =COUNTIFS(donnée!AN:AN,">=-0,25",donnée!AN:AN,"<=+0,25",donnée!CC:CC,"oui") -> 0 | T36: =COUNTIFS(donnée!AN:AN,">=-0,25",donnée!AN:AN,"<=+0,25",donnée!CD:CD,"oui") -> 0 | U36: =COUNTIFS(donnée!AN:AN,">=-0,25",donnée!AN:AN,"<=+0,25",donnée!CE:CE,"oui") -> 0 | V36: =COUNTIFS(donnée!AN:AN,">=-0,25",donnée!AN:AN,"<=+0,25",donnée!CF:CF,"oui") -> 0 | W36: +0,25 à -0,25 | X36: =COUNTIFS(donnée!AN:AN,">=-0,25",donnée!AN:AN,"<=+0,25",donnée!CG:CG,"oui") -> 0 | Y36: =COUNTIFS(donnée!AN:AN,">=-0,25",donnée!AN:AN,"<=+0,25",donnée!CH:CH,"oui") -> 0 | Z36: =COUNTIFS(donnée!AN:AN,">=-0,25",donnée!AN:AN,"<=+0,25",donnée!CI:CI,"oui") -> 0 | AA36: =COUNTIFS(donnée!AN:AN,">=-0,25",donnée!AN:AN,"<=+0,25",donnée!CJ:CJ,"oui") -> 0 | AB36: =COUNTIFS(donnée!AN:AN,">=-0,25",donnée!AN:AN,"<=+0,25",donnée!CK:CK,"oui") -> 0 | AD36: +0,25 à -0,25 | AE36: =COUNTIFS(donnée!AN:AN,">=-0,25",donnée!AN:AN,"<=+0,25",donnée!CL:CL,"oui") -> 0 | AF36: =COUNTIFS(donnée!AN:AN,">=-0,25",donnée!AN:AN,"<=+0,25",donnée!CM:CM,"oui") -> 0 | AG36: =COUNTIFS(donnée!AN:AN,">=-0,25",donnée!AN:AN,"<=+0,25",donnée!CN:CN,"oui") -> 0 | AH36: =COUNTIFS(donnée!AN:AN,">=-0,25",donnée!AN:AN,"<=+0,25",donnée!CO:CO,"oui") -> 0 | AK36: +0,25 à -0,25 | AL36: =COUNTIFS(donnée!AN:AN,">=-0,25",donnée!AN:AN,"<=+0,25",donnée!CP:CP,"oui") -> 0 | AM36: =COUNTIFS(donnée!AN:AN,">=-0,25",donnée!AN:AN,"<=+0,25",donnée!CQ:CQ,"oui") -> 0 | AN36: =COUNTIFS(donnée!AN:AN,">=-0,25",donnée!AN:AN,"<=+0,25",donnée!CR:CR,"oui") -> 0 | AO36: =COUNTIFS(donnée!AN:AN,">=-0,25",donnée!AN:AN,"<=+0,25",donnée!CS:CS,"oui") -> 0 | AR36: +0,25 à -0,25 | AS36: =COUNTIFS(donnée!$AN:$AN,">=-0,25",donnée!$AN:$AN,"<=+0,25",donnée!CT:CT,"oui") -> 0 | AT36: =COUNTIFS(donnée!$AN:$AN,">=-0,25",donnée!$AN:$AN,"<=+0,25",donnée!CU:CU,"oui") -> 0 | AU36: =COUNTIFS(donnée!$AN:$AN,">=-0,25",donnée!$AN:$AN,"<=+0,25",donnée!CV:CV,"oui") -> 0 | AV36: =COUNTIFS(donnée!$AN:$AN,">=-0,25",donnée!$AN:$AN,"<=+0,25",donnée!CW:CW,"oui") -> 0 | AW36: =COUNTIFS(donnée!$AN:$AN,">=-0,25",donnée!$AN:$AN,"<=+0,25",donnée!CX:CX,"oui") -> 0 | AX36: =COUNTIFS(donnée!$AN:$AN,">=-0,25",donnée!$AN:$AN,"<=+0,25",donnée!CY:CY,"oui") -> 0 | AY36: =COUNTIFS(donnée!$AN:$AN,">=-0,25",donnée!$AN:$AN,"<=+0,25",donnée!CZ:CZ,"oui") -> 0
